Workbook
Name DataSM: #REF!

Sheet Арсеналски
A1: Обект | B1: СМ Арсеналски | E1: C:C | F1: =SUM(C:C) -> -21745.509 | G1: 03,01,2026/11,15ч
A2: Брой съвпадения | B2: =COUNTIF(data!D:D,B1) -> 92 | E2: Начално с-до | F2: 102483.53
A3: Дата | B3: Артикул | C3: Стойност | D3: Забележка | E3: САЛДО | F3: =F1+F2 -> 80738.021
A4: {=IF(ROWS(A$4:A4)<=$B$2,INDEX(data!C$3:C$106299,SMALL(IF(data!$D$3:$D$106299=$B$1,ROW($A$2:$A$99132)-ROW($A$2)+1),ROWS(A$4:A4))),"")} -> 44557 | B4: {=IF(ROWS(B$4:B4)<=$B$2,INDEX(data!A$3:A$106299,SMALL(IF(data!$D$3:$D$106299=$B$1,ROW($A$2:$A$99132)-ROW($A$2)+1),ROWS(B$4:B4))),"")} -> MYPOS Бакалия | C4: {=IF(ROWS(C$4:C4)<=$B$2,INDEX(data!B$3:B$106299,SMALL(IF(data!$D$3:$D$106299=$B$1,ROW($A$2:$A$99132)-ROW($A$2)+1),ROWS(C$4:C4))),"")} -> -0.01 | D4: {=IF(ROWS(D$4:D4)<=$B$2,INDEX(data!E$3:E$106299,SMALL(IF(data!$D$3:$D$106299=$B$1,ROW($A$2:$A$99132)-ROW($A$2)+1),ROWS(D$4:D4))),"")}
A5: {=IF(ROWS(A$4:A5)<=$B$2,INDEX(data!C$3:C$106299,SMALL(IF(data!$D$3:$D$106299=$B$1,ROW($A$2:$A$99132)-ROW($A$2)+1),ROWS(A$4:A5))),"")} -> 46025 | B5: {=IF(ROWS(B$4:B5)<=$B$2,INDEX(data!A$3:A$106299,SMALL(IF(data!$D$3:$D$106299=$B$1,ROW($A$2:$A$99132)-ROW($A$2)+1),ROWS(B$4:B5))),"")} -> ЗАЕМ | C5: {=IF(ROWS(C$4:C5)<=$B$2,INDEX(data!B$3:B$106299,SMALL(IF(data!$D$3:$D$106299=$B$1,ROW($A$2:$A$99132)-ROW($A$2)+1),ROWS(C$4:C5))),"")} -> 10001.16 | D5: {=IF(ROWS(D$4:D5)<=$B$2,INDEX(data!E$3:E$106299,SMALL(IF(data!$D$3:$D$106299=$B$1,ROW($A$2:$A$99132)-ROW($A$2)+1),ROWS(D$4:D5))),"")} -> Салдо скл + вътр. п-не
A6: {=IF(ROWS(A$4:A6)<=$B$2,INDEX(data!C$3:C$106299,SMALL(IF(data!$D$3:$D$106299=$B$1,ROW($A$2:$A$99132)-ROW($A$2)+1),ROWS(A$4:A6))),"")} -> 46027 | B6: {=IF(ROWS(B$4:B6)<=$B$2,INDEX(data!A$3:A$106299,SMALL(IF(data!$D$3:$D$106299=$B$1,ROW($A$2:$A$99132)-ROW($A$2)+1),ROWS(B$4:B6))),"")} -> КАСОВА КНИГА | C6: {=IF(ROWS(C$4:C6)<=$B$2,INDEX(data!B$3:B$106299,SMALL(IF(data!$D$3:$D$106299=$B$1,ROW($A$2:$A$99132)-ROW($A$2)+1),ROWS(C$4:C6))),"")} -> -766.939 | D6: {=IF(ROWS(D$4:D6)<=$B$2,INDEX(data!E$3:E$106299,SMALL(IF(data!$D$3:$D$106299=$B$1,ROW($A$2:$A$99132)-ROW($A$2)+1),ROWS(D$4:D6))),"")} -> банка 02.01
A7: {=IF(ROWS(A$4:A7)<=$B$2,INDEX(data!C$3:C$106299,SMALL(IF(data!$D$3:$D$106299=$B$1,ROW($A$2:$A$99132)-ROW($A$2)+1),ROWS(A$4:A7))),"")} -> 46027 | B7: {=IF(ROWS(B$4:B7)<=$B$2,INDEX(data!A$3:A$106299,SMALL(IF(data!$D$3:$D$106299=$B$1,ROW($A$2:$A$99132)-ROW($A$2)+1),ROWS(B$4:B7))),"")} -> MYPOS Бакалия | C7: {=IF(ROWS(C$4:C7)<=$B$2,INDEX(data!B$3:B$106299,SMALL(IF(data!$D$3:$D$106299=$B$1,ROW($A$2:$A$99132)-ROW($A$2)+1),ROWS(C$4:C7))),"")} -> -1969.27 | D7: {=IF(ROWS(D$4:D7)<=$B$2,INDEX(data!E$3:E$106299,SMALL(IF(data!$D$3:$D$106299=$B$1,ROW($A$2:$A$99132)-ROW($A$2)+1),ROWS(D$4:D7))),"")}
A8: {=IF(ROWS(A$4:A8)<=$B$2,INDEX(data!C$3:C$106299,SMALL(IF(data!$D$3:$D$106299=$B$1,ROW($A$2:$A$99132)-ROW($A$2)+1),ROWS(A$4:A8))),"")} -> 46027 | B8: {=IF(ROWS(B$4:B8)<=$B$2,INDEX(data!A$3:A$106299,SMALL(IF(data!$D$3:$D$106299=$B$1,ROW($A$2:$A$99132)-ROW($A$2)+1),ROWS(B$4:B8))),"")} -> КАСОВА КНИГА | C8: {=IF(ROWS(C$4:C8)<=$B$2,INDEX(data!B$3:B$106299,SMALL(IF(data!$D$3:$D$106299=$B$1,ROW($A$2:$A$99132)-ROW($A$2)+1),ROWS(C$4:C8))),"")} -> -511.29 | D8: {=IF(ROWS(D$4:D8)<=$B$2,INDEX(data!E$3:E$106299,SMALL(IF(data!$D$3:$D$106299=$B$1,ROW($A$2:$A$99132)-ROW($A$2)+1),ROWS(D$4:D8))),"")}
A9: {=IF(ROWS(A$4:A9)<=$B$2,INDEX(data!C$3:C$106299,SMALL(IF(data!$D$3:$D$106299=$B$1,ROW($A$2:$A$99132)-ROW($A$2)+1),ROWS(A$4:A9))),"")} -> 46027 | B9: {=IF(ROWS(B$4:B9)<=$B$2,INDEX(data!A$3:A$106299,SMALL(IF(data!$D$3:$D$106299=$B$1,ROW($A$2:$A$99132)-ROW($A$2)+1),ROWS(B$4:B9))),"")} -> MYPOS Бакалия | C9: {=IF(ROWS(C$4:C9)<=$B$2,INDEX(data!B$3:B$106299,SMALL(IF(data!$D$3:$D$106299=$B$1,ROW($A$2:$A$99132)-ROW($A$2)+1),ROWS(C$4:C9))),"")} -> -1917.13 | D9: {=IF(ROWS(D$4:D9)<=$B$2,INDEX(data!E$3:E$106299,SMALL(IF(data!$D$3:$D$106299=$B$1,ROW($A$2:$A$99132)-ROW($A$2)+1),ROWS(D$4:D9))),"")} -> 29-31,12
A10: {=IF(ROWS(A$4:A10)<=$B$2,INDEX(data!C$3:C$106299,SMALL(IF(data!$D$3:$D$106299=$B$1,ROW($A$2:$A$99132)-ROW($A$2)+1),ROWS(A$4:A10))),"")} -> 46027 | B10: {=IF(ROWS(B$4:B10)<=$B$2,INDEX(data!A$3:A$106299,SMALL(IF(data!$D$3:$D$106299=$B$1,ROW($A$2:$A$99132)-ROW($A$2)+1),ROWS(B$4:B10))),"")} -> КАСОВА КНИГА | C10: {=IF(ROWS(C$4:C10)<=$B$2,INDEX(data!B$3:B$106299,SMALL(IF(data!$D$3:$D$106299=$B$1,ROW($A$2:$A$99132)-ROW($A$2)+1),ROWS(C$4:C10))),"")} -> 5110 | D10: {=IF(ROWS(D$4:D10)<=$B$2,INDEX(data!E$3:E$106299,SMALL(IF(data!$D$3:$D$106299=$B$1,ROW($A$2:$A$99132)-ROW($A$2)+1),ROWS(D$4:D10))),"")} -> евро
A11: {=IF(ROWS(A$4:A11)<=$B$2,INDEX(data!C$3:C$106299,SMALL(IF(data!$D$3:$D$106299=$B$1,ROW($A$2:$A$99132)-ROW($A$2)+1),ROWS(A$4:A11))),"")} -> 46029 | B11: {=IF(ROWS(B$4:B11)<=$B$2,INDEX(data!A$3:A$106299,SMALL(IF(data!$D$3:$D$106299=$B$1,ROW($A$2:$A$99132)-ROW($A$2)+1),ROWS(B$4:B11))),"")} -> КАСОВА КНИГА | C11: {=IF(ROWS(C$4:C11)<=$B$2,INDEX(data!B$3:B$106299,SMALL(IF(data!$D$3:$D$106299=$B$1,ROW($A$2:$A$99132)-ROW($A$2)+1),ROWS(C$4:C11))),"")} -> -2000 | D11: {=IF(ROWS(D$4:D11)<=$B$2,INDEX(data!E$3:E$106299,SMALL(IF(data!$D$3:$D$106299=$B$1,ROW($A$2:$A$99132)-ROW($A$2)+1),ROWS(D$4:D11))),"")}
A12: {=IF(ROWS(A$4:A12)<=$B$2,INDEX(data!C$3:C$106299,SMALL(IF(data!$D$3:$D$106299=$B$1,ROW($A$2:$A$99132)-ROW($A$2)+1),ROWS(A$4:A12))),"")} -> 46035 | B12: {=IF(ROWS(B$4:B12)<=$B$2,INDEX(data!A$3:A$106299,SMALL(IF(data!$D$3:$D$106299=$B$1,ROW($A$2:$A$99132)-ROW($A$2)+1),ROWS(B$4:B12))),"")} -> MYPOS Бакалия | C12: {=IF(ROWS(C$4:C12)<=$B$2,INDEX(data!B$3:B$106299,SMALL(IF(data!$D$3:$D$106299=$B$1,ROW($A$2:$A$99132)-ROW($A$2)+1),ROWS(C$4:C12))),"")} -> -5987.93 | D12: {=IF(ROWS(D$4:D12)<=$B$2,INDEX(data!E$3:E$106299,SMALL(IF(data!$D$3:$D$106299=$B$1,ROW($A$2:$A$99132)-ROW($A$2)+1),ROWS(D$4:D12))),"")}
A13: {=IF(ROWS(A$4:A13)<=$B$2,INDEX(data!C$3:C$106299,SMALL(IF(data!$D$3:$D$106299=$B$1,ROW($A$2:$A$99132)-ROW($A$2)+1),ROWS(A$4:A13))),"")} -> 46041 | B13: {=IF(ROWS(B$4:B13)<=$B$2,INDEX(data!A$3:A$106299,SMALL(IF(data!$D$3:$D$106299=$B$1,ROW($A$2:$A$99132)-ROW($A$2)+1),ROWS(B$4:B13))),"")} -> MYPOS Бакалия | C13: {=IF(ROWS(C$4:C13)<=$B$2,INDEX(data!B$3:B$106299,SMALL(IF(data!$D$3:$D$106299=$B$1,ROW($A$2:$A$99132)-ROW($A$2)+1),ROWS(C$4:C13))),"")} -> -6604.29 | D13: {=IF(ROWS(D$4:D13)<=$B$2,INDEX(data!E$3:E$106299,SMALL(IF(data!$D$3:$D$106299=$B$1,ROW($A$2:$A$99132)-ROW($A$2)+1),ROWS(D$4:D13))),"")}
A14: {=IF(ROWS(A$4:A14)<=$B$2,INDEX(data!C$3:C$106299,SMALL(IF(data!$D$3:$D$106299=$B$1,ROW($A$2:$A$99132)-ROW($A$2)+1),ROWS(A$4:A14))),"")} -> 46041 | B14: {=IF(ROWS(B$4:B14)<=$B$2,INDEX(data!A$3:A$106299,SMALL(IF(data!$D$3:$D$106299=$B$1,ROW($A$2:$A$99132)-ROW($A$2)+1),ROWS(B$4:B14))),"")} -> КАСОВА КНИГА | C14: {=IF(ROWS(C$4:C14)<=$B$2,INDEX(data!B$3:B$106299,SMALL(IF(data!$D$3:$D$106299=$B$1,ROW($A$2:$A$99132)-ROW($A$2)+1),ROWS(C$4:C14))),"")} -> -222 | D14: {=IF(ROWS(D$4:D14)<=$B$2,INDEX(data!E$3:E$106299,SMALL(IF(data!$D$3:$D$106299=$B$1,ROW($A$2:$A$99132)-ROW($A$2)+1),ROWS(D$4:D14))),"")}
A15: {=IF(ROWS(A$4:A15)<=$B$2,INDEX(data!C$3:C$106299,SMALL(IF(data!$D$3:$D$106299=$B$1,ROW($A$2:$A$99132)-ROW($A$2)+1),ROWS(A$4:A15))),"")} -> 46043 | B15: {=IF(ROWS(B$4:B15)<=$B$2,INDEX(data!A$3:A$106299,SMALL(IF(data!$D$3:$D$106299=$B$1,ROW($A$2:$A$99132)-ROW($A$2)+1),ROWS(B$4:B15))),"")} -> Каса ВАУЧЕРИ | C15: {=IF(ROWS(C$4:C15)<=$B$2,INDEX(data!B$3:B$106299,SMALL(IF(data!$D$3:$D$106299=$B$1,ROW($A$2:$A$99132)-ROW($A$2)+1),ROWS(C$4:C15))),"")} -> 409.03 | D15: {=IF(ROWS(D$4:D15)<=$B$2,INDEX(data!E$3:E$106299,SMALL(IF(data!$D$3:$D$106299=$B$1,ROW($A$2:$A$99132)-ROW($A$2)+1),ROWS(D$4:D15))),"")} -> ваучери персонал
... A107: {=IF(ROWS(A$4:A107)<=$B$2,INDEX(data!C$3:C$106299,SMALL(IF(data!$D$3:$D$106299=$B$1,ROW($A$2:$A$99132)-ROW($A$2)+1),ROWS(A$4:A107))),"")} | B107: {=IF(ROWS(B$4:B107)<=$B$2,INDEX(data!A$3:A$106299,SMALL(IF(data!$D$3:$D$106299=$B$1,ROW($A$2:$A$99132)-ROW($A$2)+1),ROWS(B$4:B107))),"")} | C107: {=IF(ROWS(C$4:C107)<=$B$2,INDEX(data!B$3:B$106299,SMALL(IF(data!$D$3:$D$106299=$B$1,ROW($A$2:$A$99132)-ROW($A$2)+1),ROWS(C$4:C107))),"")} | D107: {=IF(ROWS(D$4:D107)<=$B$2,INDEX(data!E$3:E$106299,SMALL(IF(data!$D$3:$D$106299=$B$1,ROW($A$2:$A$99132)-ROW($A$2)+1),ROWS(D$4:D107))),"")}

Sheet Банкя
A1: Обект | B1: СМ Банкя | E1: C:C | F1: =SUM(C:C) -> -46907.951 | G1: 03,01,2026/11,15ч
A2: Брой съвпадения | B2: =COUNTIF(data!D:D,B1) -> 135 | E2: Начално с-до | F2: 132498.49
A3: Дата | B3: Артикул | C3: Стойност | D3: Забележка | E3: САЛДО | F3: =F1+F2 -> 85590.539
A4: {=IF(ROWS(A$4:A4)<=$B$2,INDEX(data!C$3:C$16128,SMALL(IF(data!$D$3:$D$16128='Банкя'!$B$1,ROW(data!$A$3:$A$16128)-ROW($A$3)+1),ROWS(A$4:A4))),"")} -> 44557 | B4: {=IF(ROWS(B$4:B4)<=$B$2,INDEX(data!A$3:A$16128,SMALL(IF(data!$D$3:$D$16128=$B$1,ROW(data!$A$3:$A$16128)-ROW($A$3)+1),ROWS(B$4:B4))),"")} -> MYPOS Бакалия | C4: {=IF(ROWS(C$4:C4)<=$B$2,INDEX(data!B$3:B$16128,SMALL(IF(data!$D$3:$D$16128='Банкя'!$B$1,ROW(data!$A$3:$A$16128)-ROW($A$3)+1),ROWS(C$4:C4))),"")} -> -0.01 | D4: {=IF(ROWS(D$4:D4)<=$B$2,INDEX(data!E$3:E$16128,SMALL(IF(data!$D$3:$D$16128='Банкя'!$B$1,ROW(data!$A$3:$A$16128)-ROW($A$3)+1),ROWS(D$4:D4))),"")}
A5: {=IF(ROWS(A$4:A5)<=$B$2,INDEX(data!C$3:C$16128,SMALL(IF(data!$D$3:$D$16128='Банкя'!$B$1,ROW(data!$A$3:$A$16128)-ROW($A$3)+1),ROWS(A$4:A5))),"")} -> 46025 | B5: {=IF(ROWS(B$4:B5)<=$B$2,INDEX(data!A$3:A$16128,SMALL(IF(data!$D$3:$D$16128=$B$1,ROW(data!$A$3:$A$16128)-ROW($A$3)+1),ROWS(B$4:B5))),"")} -> ЗАЕМ | C5: {=IF(ROWS(C$4:C5)<=$B$2,INDEX(data!B$3:B$16128,SMALL(IF(data!$D$3:$D$16128='Банкя'!$B$1,ROW(data!$A$3:$A$16128)-ROW($A$3)+1),ROWS(C$4:C5))),"")} -> 7469.02 | D5: {=IF(ROWS(D$4:D5)<=$B$2,INDEX(data!E$3:E$16128,SMALL(IF(data!$D$3:$D$16128='Банкя'!$B$1,ROW(data!$A$3:$A$16128)-ROW($A$3)+1),ROWS(D$4:D5))),"")} -> Салдо скл + вътр. п-не
A6: {=IF(ROWS(A$4:A6)<=$B$2,INDEX(data!C$3:C$16128,SMALL(IF(data!$D$3:$D$16128='Банкя'!$B$1,ROW(data!$A$3:$A$16128)-ROW($A$3)+1),ROWS(A$4:A6))),"")} -> 46027 | B6: {=IF(ROWS(B$4:B6)<=$B$2,INDEX(data!A$3:A$16128,SMALL(IF(data!$D$3:$D$16128=$B$1,ROW(data!$A$3:$A$16128)-ROW($A$3)+1),ROWS(B$4:B6))),"")} -> КАСОВА КНИГА | C6: {=IF(ROWS(C$4:C6)<=$B$2,INDEX(data!B$3:B$16128,SMALL(IF(data!$D$3:$D$16128='Банкя'!$B$1,ROW(data!$A$3:$A$16128)-ROW($A$3)+1),ROWS(C$4:C6))),"")} -> -3579.04 | D6: {=IF(ROWS(D$4:D6)<=$B$2,INDEX(data!E$3:E$16128,SMALL(IF(data!$D$3:$D$16128='Банкя'!$B$1,ROW(data!$A$3:$A$16128)-ROW($A$3)+1),ROWS(D$4:D6))),"")} -> банка 02.01
A7: {=IF(ROWS(A$4:A7)<=$B$2,INDEX(data!C$3:C$16128,SMALL(IF(data!$D$3:$D$16128='Банкя'!$B$1,ROW(data!$A$3:$A$16128)-ROW($A$3)+1),ROWS(A$4:A7))),"")} -> 46027 | B7: {=IF(ROWS(B$4:B7)<=$B$2,INDEX(data!A$3:A$16128,SMALL(IF(data!$D$3:$D$16128=$B$1,ROW(data!$A$3:$A$16128)-ROW($A$3)+1),ROWS(B$4:B7))),"")} -> MYPOS Бакалия | C7: {=IF(ROWS(C$4:C7)<=$B$2,INDEX(data!B$3:B$16128,SMALL(IF(data!$D$3:$D$16128='Банкя'!$B$1,ROW(data!$A$3:$A$16128)-ROW($A$3)+1),ROWS(C$4:C7))),"")} -> -528.47 | D7: {=IF(ROWS(D$4:D7)<=$B$2,INDEX(data!E$3:E$16128,SMALL(IF(data!$D$3:$D$16128='Банкя'!$B$1,ROW(data!$A$3:$A$16128)-ROW($A$3)+1),ROWS(D$4:D7))),"")}
A8: {=IF(ROWS(A$4:A8)<=$B$2,INDEX(data!C$3:C$16128,SMALL(IF(data!$D$3:$D$16128='Банкя'!$B$1,ROW(data!$A$3:$A$16128)-ROW($A$3)+1),ROWS(A$4:A8))),"")} -> 46027 | B8: {=IF(ROWS(B$4:B8)<=$B$2,INDEX(data!A$3:A$16128,SMALL(IF(data!$D$3:$D$16128=$B$1,ROW(data!$A$3:$A$16128)-ROW($A$3)+1),ROWS(B$4:B8))),"")} -> MYPOS Бакалия | C8: {=IF(ROWS(C$4:C8)<=$B$2,INDEX(data!B$3:B$16128,SMALL(IF(data!$D$3:$D$16128='Банкя'!$B$1,ROW(data!$A$3:$A$16128)-ROW($A$3)+1),ROWS(C$4:C8))),"")} -> -974.32 | D8: {=IF(ROWS(D$4:D8)<=$B$2,INDEX(data!E$3:E$16128,SMALL(IF(data!$D$3:$D$16128='Банкя'!$B$1,ROW(data!$A$3:$A$16128)-ROW($A$3)+1),ROWS(D$4:D8))),"")} -> 29-31,12
A9: {=IF(ROWS(A$4:A9)<=$B$2,INDEX(data!C$3:C$16128,SMALL(IF(data!$D$3:$D$16128='Банкя'!$B$1,ROW(data!$A$3:$A$16128)-ROW($A$3)+1),ROWS(A$4:A9))),"")} -> 46027 | B9: {=IF(ROWS(B$4:B9)<=$B$2,INDEX(data!A$3:A$16128,SMALL(IF(data!$D$3:$D$16128=$B$1,ROW(data!$A$3:$A$16128)-ROW($A$3)+1),ROWS(B$4:B9))),"")} -> КАСОВА КНИГА | C9: {=IF(ROWS(C$4:C9)<=$B$2,INDEX(data!B$3:B$16128,SMALL(IF(data!$D$3:$D$16128='Банкя'!$B$1,ROW(data!$A$3:$A$16128)-ROW($A$3)+1),ROWS(C$4:C9))),"")} -> 3110 | D9: {=IF(ROWS(D$4:D9)<=$B$2,INDEX(data!E$3:E$16128,SMALL(IF(data!$D$3:$D$16128='Банкя'!$B$1,ROW(data!$A$3:$A$16128)-ROW($A$3)+1),ROWS(D$4:D9))),"")} -> евро
A10: {=IF(ROWS(A$4:A10)<=$B$2,INDEX(data!C$3:C$16128,SMALL(IF(data!$D$3:$D$16128='Банкя'!$B$1,ROW(data!$A$3:$A$16128)-ROW($A$3)+1),ROWS(A$4:A10))),"")} -> 46028 | B10: {=IF(ROWS(B$4:B10)<=$B$2,INDEX(data!A$3:A$16128,SMALL(IF(data!$D$3:$D$16128=$B$1,ROW(data!$A$3:$A$16128)-ROW($A$3)+1),ROWS(B$4:B10))),"")} -> каса ФИКТИВНА | C10: {=IF(ROWS(C$4:C10)<=$B$2,INDEX(data!B$3:B$16128,SMALL(IF(data!$D$3:$D$16128='Банкя'!$B$1,ROW(data!$A$3:$A$16128)-ROW($A$3)+1),ROWS(C$4:C10))),"")} -> -102.26 | D10: {=IF(ROWS(D$4:D10)<=$B$2,INDEX(data!E$3:E$16128,SMALL(IF(data!$D$3:$D$16128='Банкя'!$B$1,ROW(data!$A$3:$A$16128)-ROW($A$3)+1),ROWS(D$4:D10))),"")} -> Стаси от заплатата
A11: {=IF(ROWS(A$4:A11)<=$B$2,INDEX(data!C$3:C$16128,SMALL(IF(data!$D$3:$D$16128='Банкя'!$B$1,ROW(data!$A$3:$A$16128)-ROW($A$3)+1),ROWS(A$4:A11))),"")} -> 46029 | B11: {=IF(ROWS(B$4:B11)<=$B$2,INDEX(data!A$3:A$16128,SMALL(IF(data!$D$3:$D$16128=$B$1,ROW(data!$A$3:$A$16128)-ROW($A$3)+1),ROWS(B$4:B11))),"")} -> КАСОВА КНИГА | C11: {=IF(ROWS(C$4:C11)<=$B$2,INDEX(data!B$3:B$16128,SMALL(IF(data!$D$3:$D$16128='Банкя'!$B$1,ROW(data!$A$3:$A$16128)-ROW($A$3)+1),ROWS(C$4:C11))),"")} -> -511.29 | D11: {=IF(ROWS(D$4:D11)<=$B$2,INDEX(data!E$3:E$16128,SMALL(IF(data!$D$3:$D$16128='Банкя'!$B$1,ROW(data!$A$3:$A$16128)-ROW($A$3)+1),ROWS(D$4:D11))),"")}
A12: {=IF(ROWS(A$4:A12)<=$B$2,INDEX(data!C$3:C$16128,SMALL(IF(data!$D$3:$D$16128='Банкя'!$B$1,ROW(data!$A$3:$A$16128)-ROW($A$3)+1),ROWS(A$4:A12))),"")} -> 46030 | B12: {=IF(ROWS(B$4:B12)<=$B$2,INDEX(data!A$3:A$16128,SMALL(IF(data!$D$3:$D$16128=$B$1,ROW(data!$A$3:$A$16128)-ROW($A$3)+1),ROWS(B$4:B12))),"")} -> Каса ВАУЧЕРИ | C12: {=IF(ROWS(C$4:C12)<=$B$2,INDEX(data!B$3:B$16128,SMALL(IF(data!$D$3:$D$16128='Банкя'!$B$1,ROW(data!$A$3:$A$16128)-ROW($A$3)+1),ROWS(C$4:C12))),"")} -> -5.11 | D12: {=IF(ROWS(D$4:D12)<=$B$2,INDEX(data!E$3:E$16128,SMALL(IF(data!$D$3:$D$16128='Банкя'!$B$1,ROW(data!$A$3:$A$16128)-ROW($A$3)+1),ROWS(D$4:D12))),"")} -> за 22.12
A13: {=IF(ROWS(A$4:A13)<=$B$2,INDEX(data!C$3:C$16128,SMALL(IF(data!$D$3:$D$16128='Банкя'!$B$1,ROW(data!$A$3:$A$16128)-ROW($A$3)+1),ROWS(A$4:A13))),"")} -> 46031 | B13: {=IF(ROWS(B$4:B13)<=$B$2,INDEX(data!A$3:A$16128,SMALL(IF(data!$D$3:$D$16128=$B$1,ROW(data!$A$3:$A$16128)-ROW($A$3)+1),ROWS(B$4:B13))),"")} -> КАСОВА КНИГА | C13: {=IF(ROWS(C$4:C13)<=$B$2,INDEX(data!B$3:B$16128,SMALL(IF(data!$D$3:$D$16128='Банкя'!$B$1,ROW(data!$A$3:$A$16128)-ROW($A$3)+1),ROWS(C$4:C13))),"")} -> -1000 | D13: {=IF(ROWS(D$4:D13)<=$B$2,INDEX(data!E$3:E$16128,SMALL(IF(data!$D$3:$D$16128='Банкя'!$B$1,ROW(data!$A$3:$A$16128)-ROW($A$3)+1),ROWS(D$4:D13))),"")}
A14: {=IF(ROWS(A$4:A14)<=$B$2,INDEX(data!C$3:C$16128,SMALL(IF(data!$D$3:$D$16128='Банкя'!$B$1,ROW(data!$A$3:$A$16128)-ROW($A$3)+1),ROWS(A$4:A14))),"")} -> 46034 | B14: {=IF(ROWS(B$4:B14)<=$B$2,INDEX(data!A$3:A$16128,SMALL(IF(data!$D$3:$D$16128=$B$1,ROW(data!$A$3:$A$16128)-ROW($A$3)+1),ROWS(B$4:B14))),"")} -> КАСОВА КНИГА | C14: {=IF(ROWS(C$4:C14)<=$B$2,INDEX(data!B$3:B$16128,SMALL(IF(data!$D$3:$D$16128='Банкя'!$B$1,ROW(data!$A$3:$A$16128)-ROW($A$3)+1),ROWS(C$4:C14))),"")} -> -3022.58 | D14: {=IF(ROWS(D$4:D14)<=$B$2,INDEX(data!E$3:E$16128,SMALL(IF(data!$D$3:$D$16128='Банкя'!$B$1,ROW(data!$A$3:$A$16128)-ROW($A$3)+1),ROWS(D$4:D14))),"")}
A15: {=IF(ROWS(A$4:A15)<=$B$2,INDEX(data!C$3:C$16128,SMALL(IF(data!$D$3:$D$16128='Банкя'!$B$1,ROW(data!$A$3:$A$16128)-ROW($A$3)+1),ROWS(A$4:A15))),"")} -> 46035 | B15: {=IF(ROWS(B$4:B15)<=$B$2,INDEX(data!A$3:A$16128,SMALL(IF(data!$D$3:$D$16128=$B$1,ROW(data!$A$3:$A$16128)-ROW($A$3)+1),ROWS(B$4:B15))),"")} -> MYPOS Бакалия | C15: {=IF(ROWS(C$4:C15)<=$B$2,INDEX(data!B$3:B$16128,SMALL(IF(data!$D$3:$D$16128='Банкя'!$B$1,ROW(data!$A$3:$A$16128)-ROW($A$3)+1),ROWS(C$4:C15))),"")} -> -2123.24 | D15: {=IF(ROWS(D$4:D15)<=$B$2,INDEX(data!E$3:E$16128,SMALL(IF(data!$D$3:$D$16128='Банкя'!$B$1,ROW(data!$A$3:$A$16128)-ROW($A$3)+1),ROWS(D$4:D15))),"")}
... A147: {=IF(ROWS(A$4:A147)<=$B$2,INDEX(data!C$3:C$16128,SMALL(IF(data!$D$3:$D$16128='Банкя'!$B$1,ROW(data!$A$3:$A$16128)-ROW($A$3)+1),ROWS(A$4:A147))),"")} | B147: {=IF(ROWS(B$4:B147)<=$B$2,INDEX(data!A$3:A$16128,SMALL(IF(data!$D$3:$D$16128=$B$1,ROW(data!$A$3:$A$16128)-ROW($A$3)+1),ROWS(B$4:B147))),"")} | C147: {=IF(ROWS(C$4:C147)<=$B$2,INDEX(data!B$3:B$16128,SMALL(IF(data!$D$3:$D$16128='Банкя'!$B$1,ROW(data!$A$3:$A$16128)-ROW($A$3)+1),ROWS(C$4:C147))),"")} | D147: {=IF(ROWS(D$4:D147)<=$B$2,INDEX(data!E$3:E$16128,SMALL(IF(data!$D$3:$D$16128='Банкя'!$B$1,ROW(data!$A$3:$A$16128)-ROW($A$3)+1),ROWS(D$4:D147))),"")}

Sheet Велчо Атанасов
A1: 0 | B1: СМ Велчо Атанасов | E1: C:C | F1: =SUM(C:C) -> -39383.15 | G1: 03,01,2026/11,15ч
A2: Брой съвпадения | B2: =COUNTIF(data!D:D,B1) -> 141 | E2: Начално с-до | F2: 49627.51
A3: Дата | B3: Артикул | C3: Стойност | D3: Забележка | E3: САЛДО | F3: =F1+F2 -> 10244.36
A4: {=IF(ROWS(A$4:A4)<=$B$2,INDEX(data!C$3:C$16128,SMALL(IF(data!$D$3:$D$16128='Велчо Атанасов'!$B$1,ROW(data!$A$3:$A$16128)-ROW($A$3)+1),ROWS(A$4:A4))),"")} -> 44557 | B4: {=IF(ROWS(B$4:B4)<=$B$2,INDEX(data!A$3:A$16128,SMALL(IF(data!$D$3:$D$16128='Велчо Атанасов'!$B$1,ROW(data!$A$3:$A$16128)-ROW($A$3)+1),ROWS(B$4:B4))),"")} -> MYPOS Бакалия | C4: {=IF(ROWS(C$4:C4)<=$B$2,INDEX(data!B$3:B$16128,SMALL(IF(data!$D$3:$D$16128='Велчо Атанасов'!$B$1,ROW(data!$A$3:$A$16128)-ROW($A$3)+1),ROWS(C$4:C4))),"")} -> -0.01 | D4: {=IF(ROWS(D$4:D4)<=$B$2,INDEX(data!E$3:E$16128,SMALL(IF(data!$D$3:$D$16128='Велчо Атанасов'!$B$1,ROW(data!$A$3:$A$16128)-ROW($A$3)+1),ROWS(D$4:D4))),"")}
A5: {=IF(ROWS(A$4:A5)<=$B$2,INDEX(data!C$3:C$16128,SMALL(IF(data!$D$3:$D$16128='Велчо Атанасов'!$B$1,ROW(data!$A$3:$A$16128)-ROW($A$3)+1),ROWS(A$4:A5))),"")} -> 46025 | B5: {=IF(ROWS(B$4:B5)<=$B$2,INDEX(data!A$3:A$16128,SMALL(IF(data!$D$3:$D$16128='Велчо Атанасов'!$B$1,ROW(data!$A$3:$A$16128)-ROW($A$3)+1),ROWS(B$4:B5))),"")} -> ЗАЕМ | C5: {=IF(ROWS(C$4:C5)<=$B$2,INDEX(data!B$3:B$16128,SMALL(IF(data!$D$3:$D$16128='Велчо Атанасов'!$B$1,ROW(data!$A$3:$A$16128)-ROW($A$3)+1),ROWS(C$4:C5))),"")} -> 18711.61 | D5: {=IF(ROWS(D$4:D5)<=$B$2,INDEX(data!E$3:E$16128,SMALL(IF(data!$D$3:$D$16128='Велчо Атанасов'!$B$1,ROW(data!$A$3:$A$16128)-ROW($A$3)+1),ROWS(D$4:D5))),"")} -> Салдо скл + вътр. п-не
A6: {=IF(ROWS(A$4:A6)<=$B$2,INDEX(data!C$3:C$16128,SMALL(IF(data!$D$3:$D$16128='Велчо Атанасов'!$B$1,ROW(data!$A$3:$A$16128)-ROW($A$3)+1),ROWS(A$4:A6))),"")} -> 46027 | B6: {=IF(ROWS(B$4:B6)<=$B$2,INDEX(data!A$3:A$16128,SMALL(IF(data!$D$3:$D$16128='Велчо Атанасов'!$B$1,ROW(data!$A$3:$A$16128)-ROW($A$3)+1),ROWS(B$4:B6))),"")} -> КАСОВА КНИГА | C6: {=IF(ROWS(C$4:C6)<=$B$2,INDEX(data!B$3:B$16128,SMALL(IF(data!$D$3:$D$16128='Велчо Атанасов'!$B$1,ROW(data!$A$3:$A$16128)-ROW($A$3)+1),ROWS(C$4:C6))),"")} -> -2709.847 | D6: {=IF(ROWS(D$4:D6)<=$B$2,INDEX(data!E$3:E$16128,SMALL(IF(data!$D$3:$D$16128='Велчо Атанасов'!$B$1,ROW(data!$A$3:$A$16128)-ROW($A$3)+1),ROWS(D$4:D6))),"")} -> банка 02.01
A7: {=IF(ROWS(A$4:A7)<=$B$2,INDEX(data!C$3:C$16128,SMALL(IF(data!$D$3:$D$16128='Велчо Атанасов'!$B$1,ROW(data!$A$3:$A$16128)-ROW($A$3)+1),ROWS(A$4:A7))),"")} -> 46027 | B7: {=IF(ROWS(B$4:B7)<=$B$2,INDEX(data!A$3:A$16128,SMALL(IF(data!$D$3:$D$16128='Велчо Атанасов'!$B$1,ROW(data!$A$3:$A$16128)-ROW($A$3)+1),ROWS(B$4:B7))),"")} -> MYPOS Бакалия | C7: {=IF(ROWS(C$4:C7)<=$B$2,INDEX(data!B$3:B$16128,SMALL(IF(data!$D$3:$D$16128='Велчо Атанасов'!$B$1,ROW(data!$A$3:$A$16128)-ROW($A$3)+1),ROWS(C$4:C7))),"")} -> -4604.6 | D7: {=IF(ROWS(D$4:D7)<=$B$2,INDEX(data!E$3:E$16128,SMALL(IF(data!$D$3:$D$16128='Велчо Атанасов'!$B$1,ROW(data!$A$3:$A$16128)-ROW($A$3)+1),ROWS(D$4:D7))),"")}
A8: {=IF(ROWS(A$4:A8)<=$B$2,INDEX(data!C$3:C$16128,SMALL(IF(data!$D$3:$D$16128='Велчо Атанасов'!$B$1,ROW(data!$A$3:$A$16128)-ROW($A$3)+1),ROWS(A$4:A8))),"")} -> 46027 | B8: {=IF(ROWS(B$4:B8)<=$B$2,INDEX(data!A$3:A$16128,SMALL(IF(data!$D$3:$D$16128='Велчо Атанасов'!$B$1,ROW(data!$A$3:$A$16128)-ROW($A$3)+1),ROWS(B$4:B8))),"")} -> КАСОВА КНИГА | C8: {=IF(ROWS(C$4:C8)<=$B$2,INDEX(data!B$3:B$16128,SMALL(IF(data!$D$3:$D$16128='Велчо Атанасов'!$B$1,ROW(data!$A$3:$A$16128)-ROW($A$3)+1),ROWS(C$4:C8))),"")} -> -1533.88 | D8: {=IF(ROWS(D$4:D8)<=$B$2,INDEX(data!E$3:E$16128,SMALL(IF(data!$D$3:$D$16128='Велчо Атанасов'!$B$1,ROW(data!$A$3:$A$16128)-ROW($A$3)+1),ROWS(D$4:D8))),"")}
A9: {=IF(ROWS(A$4:A9)<=$B$2,INDEX(data!C$3:C$16128,SMALL(IF(data!$D$3:$D$16128='Велчо Атанасов'!$B$1,ROW(data!$A$3:$A$16128)-ROW($A$3)+1),ROWS(A$4:A9))),"")} -> 46027 | B9: {=IF(ROWS(B$4:B9)<=$B$2,INDEX(data!A$3:A$16128,SMALL(IF(data!$D$3:$D$16128='Велчо Атанасов'!$B$1,ROW(data!$A$3:$A$16128)-ROW($A$3)+1),ROWS(B$4:B9))),"")} -> MYPOS Бакалия | C9: {=IF(ROWS(C$4:C9)<=$B$2,INDEX(data!B$3:B$16128,SMALL(IF(data!$D$3:$D$16128='Велчо Атанасов'!$B$1,ROW(data!$A$3:$A$16128)-ROW($A$3)+1),ROWS(C$4:C9))),"")} -> -5534.12 | D9: {=IF(ROWS(D$4:D9)<=$B$2,INDEX(data!E$3:E$16128,SMALL(IF(data!$D$3:$D$16128='Велчо Атанасов'!$B$1,ROW(data!$A$3:$A$16128)-ROW($A$3)+1),ROWS(D$4:D9))),"")} -> 29-31,12
A10: {=IF(ROWS(A$4:A10)<=$B$2,INDEX(data!C$3:C$16128,SMALL(IF(data!$D$3:$D$16128='Велчо Атанасов'!$B$1,ROW(data!$A$3:$A$16128)-ROW($A$3)+1),ROWS(A$4:A10))),"")} -> 46027 | B10: {=IF(ROWS(B$4:B10)<=$B$2,INDEX(data!A$3:A$16128,SMALL(IF(data!$D$3:$D$16128='Велчо Атанасов'!$B$1,ROW(data!$A$3:$A$16128)-ROW($A$3)+1),ROWS(B$4:B10))),"")} -> КАСОВА КНИГА | C10: {=IF(ROWS(C$4:C10)<=$B$2,INDEX(data!B$3:B$16128,SMALL(IF(data!$D$3:$D$16128='Велчо Атанасов'!$B$1,ROW(data!$A$3:$A$16128)-ROW($A$3)+1),ROWS(C$4:C10))),"")} -> 5110 | D10: {=IF(ROWS(D$4:D10)<=$B$2,INDEX(data!E$3:E$16128,SMALL(IF(data!$D$3:$D$16128='Велчо Атанасов'!$B$1,ROW(data!$A$3:$A$16128)-ROW($A$3)+1),ROWS(D$4:D10))),"")} -> евро
A11: {=IF(ROWS(A$4:A11)<=$B$2,INDEX(data!C$3:C$16128,SMALL(IF(data!$D$3:$D$16128='Велчо Атанасов'!$B$1,ROW(data!$A$3:$A$16128)-ROW($A$3)+1),ROWS(A$4:A11))),"")} -> 46028 | B11: {=IF(ROWS(B$4:B11)<=$B$2,INDEX(data!A$3:A$16128,SMALL(IF(data!$D$3:$D$16128='Велчо Атанасов'!$B$1,ROW(data!$A$3:$A$16128)-ROW($A$3)+1),ROWS(B$4:B11))),"")} -> каса ФИКТИВНА | C11: {=IF(ROWS(C$4:C11)<=$B$2,INDEX(data!B$3:B$16128,SMALL(IF(data!$D$3:$D$16128='Велчо Атанасов'!$B$1,ROW(data!$A$3:$A$16128)-ROW($A$3)+1),ROWS(C$4:C11))),"")} -> -600 | D11: {=IF(ROWS(D$4:D11)<=$B$2,INDEX(data!E$3:E$16128,SMALL(IF(data!$D$3:$D$16128='Велчо Атанасов'!$B$1,ROW(data!$A$3:$A$16128)-ROW($A$3)+1),ROWS(D$4:D11))),"")} -> Ева от премиите
A12: {=IF(ROWS(A$4:A12)<=$B$2,INDEX(data!C$3:C$16128,SMALL(IF(data!$D$3:$D$16128='Велчо Атанасов'!$B$1,ROW(data!$A$3:$A$16128)-ROW($A$3)+1),ROWS(A$4:A12))),"")} -> 46030 | B12: {=IF(ROWS(B$4:B12)<=$B$2,INDEX(data!A$3:A$16128,SMALL(IF(data!$D$3:$D$16128='Велчо Атанасов'!$B$1,ROW(data!$A$3:$A$16128)-ROW($A$3)+1),ROWS(B$4:B12))),"")} -> КАСОВА КНИГА | C12: {=IF(ROWS(C$4:C12)<=$B$2,INDEX(data!B$3:B$16128,SMALL(IF(data!$D$3:$D$16128='Велчо Атанасов'!$B$1,ROW(data!$A$3:$A$16128)-ROW($A$3)+1),ROWS(C$4:C12))),"")} -> 777 | D12: {=IF(ROWS(D$4:D12)<=$B$2,INDEX(data!E$3:E$16128,SMALL(IF(data!$D$3:$D$16128='Велчо Атанасов'!$B$1,ROW(data!$A$3:$A$16128)-ROW($A$3)+1),ROWS(D$4:D12))),"")} -> заем
A13: {=IF(ROWS(A$4:A13)<=$B$2,INDEX(data!C$3:C$16128,SMALL(IF(data!$D$3:$D$16128='Велчо Атанасов'!$B$1,ROW(data!$A$3:$A$16128)-ROW($A$3)+1),ROWS(A$4:A13))),"")} -> 46030 | B13: {=IF(ROWS(B$4:B13)<=$B$2,INDEX(data!A$3:A$16128,SMALL(IF(data!$D$3:$D$16128='Велчо Атанасов'!$B$1,ROW(data!$A$3:$A$16128)-ROW($A$3)+1),ROWS(B$4:B13))),"")} -> Каса ВАУЧЕРИ | C13: {=IF(ROWS(C$4:C13)<=$B$2,INDEX(data!B$3:B$16128,SMALL(IF(data!$D$3:$D$16128='Велчо Атанасов'!$B$1,ROW(data!$A$3:$A$16128)-ROW($A$3)+1),ROWS(C$4:C13))),"")} -> -250.53 | D13: {=IF(ROWS(D$4:D13)<=$B$2,INDEX(data!E$3:E$16128,SMALL(IF(data!$D$3:$D$16128='Велчо Атанасов'!$B$1,ROW(data!$A$3:$A$16128)-ROW($A$3)+1),ROWS(D$4:D13))),"")} -> за 22.12
A14: {=IF(ROWS(A$4:A14)<=$B$2,INDEX(data!C$3:C$16128,SMALL(IF(data!$D$3:$D$16128='Велчо Атанасов'!$B$1,ROW(data!$A$3:$A$16128)-ROW($A$3)+1),ROWS(A$4:A14))),"")} -> 46030 | B14: {=IF(ROWS(B$4:B14)<=$B$2,INDEX(data!A$3:A$16128,SMALL(IF(data!$D$3:$D$16128='Велчо Атанасов'!$B$1,ROW(data!$A$3:$A$16128)-ROW($A$3)+1),ROWS(B$4:B14))),"")} -> Каса ВАУЧЕРИ | C14: {=IF(ROWS(C$4:C14)<=$B$2,INDEX(data!B$3:B$16128,SMALL(IF(data!$D$3:$D$16128='Велчо Атанасов'!$B$1,ROW(data!$A$3:$A$16128)-ROW($A$3)+1),ROWS(C$4:C14))),"")} -> -76.69 | D14: {=IF(ROWS(D$4:D14)<=$B$2,INDEX(data!E$3:E$16128,SMALL(IF(data!$D$3:$D$16128='Велчо Атанасов'!$B$1,ROW(data!$A$3:$A$16128)-ROW($A$3)+1),ROWS(D$4:D14))),"")} -> за 29.12
A15: {=IF(ROWS(A$4:A15)<=$B$2,INDEX(data!C$3:C$16128,SMALL(IF(data!$D$3:$D$16128='Велчо Атанасов'!$B$1,ROW(data!$A$3:$A$16128)-ROW($A$3)+1),ROWS(A$4:A15))),"")} -> 46031 | B15: {=IF(ROWS(B$4:B15)<=$B$2,INDEX(data!A$3:A$16128,SMALL(IF(data!$D$3:$D$16128='Велчо Атанасов'!$B$1,ROW(data!$A$3:$A$16128)-ROW($A$3)+1),ROWS(B$4:B15))),"")} -> КАСОВА КНИГА | C15: {=IF(ROWS(C$4:C15)<=$B$2,INDEX(data!B$3:B$16128,SMALL(IF(data!$D$3:$D$16128='Велчо Атанасов'!$B$1,ROW(data!$A$3:$A$16128)-ROW($A$3)+1),ROWS(C$4:C15))),"")} -> -1000 | D15: {=IF(ROWS(D$4:D15)<=$B$2,INDEX(data!E$3:E$16128,SMALL(IF(data!$D$3:$D$16128='Велчо Атанасов'!$B$1,ROW(data!$A$3:$A$16128)-ROW($A$3)+1),ROWS(D$4:D15))),"")}
... A160: {=IF(ROWS(A$4:A160)<=$B$2,INDEX(data!C$3:C$16128,SMALL(IF(data!$D$3:$D$16128='Велчо Атанасов'!$B$1,ROW(data!$A$3:$A$16128)-ROW($A$3)+1),ROWS(A$4:A160))),"")} | B160: {=IF(ROWS(B$4:B160)<=$B$2,INDEX(data!A$3:A$16128,SMALL(IF(data!$D$3:$D$16128='Велчо Атанасов'!$B$1,ROW(data!$A$3:$A$16128)-ROW($A$3)+1),ROWS(B$4:B160))),"")} | C160: {=IF(ROWS(C$4:C160)<=$B$2,INDEX(data!B$3:B$16128,SMALL(IF(data!$D$3:$D$16128='Велчо Атанасов'!$B$1,ROW(data!$A$3:$A$16128)-ROW($A$3)+1),ROWS(C$4:C160))),"")} | D160: {=IF(ROWS(D$4:D160)<=$B$2,INDEX(data!E$3:E$16128,SMALL(IF(data!$D$3:$D$16128='Велчо Атанасов'!$B$1,ROW(data!$A$3:$A$16128)-ROW($A$3)+1),ROWS(D$4:D160))),"")}

Sheet Лозeнец
A1: Обект | B1: СМ Лозенец | E1: C:C | F1: =SUM(C:C) -> -37682.497 | G1: 03,01,2026/11,15ч
A2: Брой съвпадения | B2: =COUNTIF(data!D:D,B1) -> 158 | E2: Начално с-до | F2: 80915.44
A3: Дата | B3: Артикул | C3: Стойност | D3: Забележка | E3: САЛДО | F3: =F1+F2 -> 43232.943
A4: {=IF(ROWS(A$4:A4)<=$B$2,INDEX(data!C$3:C$16128,SMALL(IF(data!$D$3:$D$16128=$B$1,ROW(data!$A$3:$A$16128)-ROW($A$3)+1),ROWS(A$4:A4))),"")} -> 44557 | B4: {=IF(ROWS(B$4:B4)<=$B$2,INDEX(data!A$3:A$16128,SMALL(IF(data!$D$3:$D$16128='Лозeнец'!$B$1,ROW(data!$A$3:$A$16128)-ROW($A$3)+1),ROWS(B$4:B4))),"")} -> MYPOS Бакалия | C4: {=IF(ROWS(C$4:C4)<=$B$2,INDEX(data!B$3:B$16128,SMALL(IF(data!$D$3:$D$16128='Лозeнец'!$B$1,ROW(data!$A$3:$A$16128)-ROW($A$3)+1),ROWS(C$4:C4))),"")} -> -0.01 | D4: {=IF(ROWS(D$4:D4)<=$B$2,INDEX(data!E$3:E$16128,SMALL(IF(data!$D$3:$D$16128='Лозeнец'!$B$1,ROW(data!$A$3:$A$16128)-ROW($A$3)+1),ROWS(D$4:D4))),"")}
A5: {=IF(ROWS(A$4:A5)<=$B$2,INDEX(data!C$3:C$16128,SMALL(IF(data!$D$3:$D$16128=$B$1,ROW(data!$A$3:$A$16128)-ROW($A$3)+1),ROWS(A$4:A5))),"")} -> 46025 | B5: {=IF(ROWS(B$4:B5)<=$B$2,INDEX(data!A$3:A$16128,SMALL(IF(data!$D$3:$D$16128='Лозeнец'!$B$1,ROW(data!$A$3:$A$16128)-ROW($A$3)+1),ROWS(B$4:B5))),"")} -> ЗАЕМ | C5: {=IF(ROWS(C$4:C5)<=$B$2,INDEX(data!B$3:B$16128,SMALL(IF(data!$D$3:$D$16128='Лозeнец'!$B$1,ROW(data!$A$3:$A$16128)-ROW($A$3)+1),ROWS(C$4:C5))),"")} -> 16789.63 | D5: {=IF(ROWS(D$4:D5)<=$B$2,INDEX(data!E$3:E$16128,SMALL(IF(data!$D$3:$D$16128='Лозeнец'!$B$1,ROW(data!$A$3:$A$16128)-ROW($A$3)+1),ROWS(D$4:D5))),"")} -> Салдо скл + вътр. п-не
A6: {=IF(ROWS(A$4:A6)<=$B$2,INDEX(data!C$3:C$16128,SMALL(IF(data!$D$3:$D$16128=$B$1,ROW(data!$A$3:$A$16128)-ROW($A$3)+1),ROWS(A$4:A6))),"")} -> 46027 | B6: {=IF(ROWS(B$4:B6)<=$B$2,INDEX(data!A$3:A$16128,SMALL(IF(data!$D$3:$D$16128='Лозeнец'!$B$1,ROW(data!$A$3:$A$16128)-ROW($A$3)+1),ROWS(B$4:B6))),"")} -> КАСОВА КНИГА | C6: {=IF(ROWS(C$4:C6)<=$B$2,INDEX(data!B$3:B$16128,SMALL(IF(data!$D$3:$D$16128='Лозeнец'!$B$1,ROW(data!$A$3:$A$16128)-ROW($A$3)+1),ROWS(C$4:C6))),"")} -> -5624.21 | D6: {=IF(ROWS(D$4:D6)<=$B$2,INDEX(data!E$3:E$16128,SMALL(IF(data!$D$3:$D$16128='Лозeнец'!$B$1,ROW(data!$A$3:$A$16128)-ROW($A$3)+1),ROWS(D$4:D6))),"")} -> банка 02.01
A7: {=IF(ROWS(A$4:A7)<=$B$2,INDEX(data!C$3:C$16128,SMALL(IF(data!$D$3:$D$16128=$B$1,ROW(data!$A$3:$A$16128)-ROW($A$3)+1),ROWS(A$4:A7))),"")} -> 46027 | B7: {=IF(ROWS(B$4:B7)<=$B$2,INDEX(data!A$3:A$16128,SMALL(IF(data!$D$3:$D$16128='Лозeнец'!$B$1,ROW(data!$A$3:$A$16128)-ROW($A$3)+1),ROWS(B$4:B7))),"")} -> MYPOS Бакалия | C7: {=IF(ROWS(C$4:C7)<=$B$2,INDEX(data!B$3:B$16128,SMALL(IF(data!$D$3:$D$16128='Лозeнец'!$B$1,ROW(data!$A$3:$A$16128)-ROW($A$3)+1),ROWS(C$4:C7))),"")} -> -3973.32 | D7: {=IF(ROWS(D$4:D7)<=$B$2,INDEX(data!E$3:E$16128,SMALL(IF(data!$D$3:$D$16128='Лозeнец'!$B$1,ROW(data!$A$3:$A$16128)-ROW($A$3)+1),ROWS(D$4:D7))),"")}
A8: {=IF(ROWS(A$4:A8)<=$B$2,INDEX(data!C$3:C$16128,SMALL(IF(data!$D$3:$D$16128=$B$1,ROW(data!$A$3:$A$16128)-ROW($A$3)+1),ROWS(A$4:A8))),"")} -> 46027 | B8: {=IF(ROWS(B$4:B8)<=$B$2,INDEX(data!A$3:A$16128,SMALL(IF(data!$D$3:$D$16128='Лозeнец'!$B$1,ROW(data!$A$3:$A$16128)-ROW($A$3)+1),ROWS(B$4:B8))),"")} -> КАСОВА КНИГА | C8: {=IF(ROWS(C$4:C8)<=$B$2,INDEX(data!B$3:B$16128,SMALL(IF(data!$D$3:$D$16128='Лозeнец'!$B$1,ROW(data!$A$3:$A$16128)-ROW($A$3)+1),ROWS(C$4:C8))),"")} -> -1789.52 | D8: {=IF(ROWS(D$4:D8)<=$B$2,INDEX(data!E$3:E$16128,SMALL(IF(data!$D$3:$D$16128='Лозeнец'!$B$1,ROW(data!$A$3:$A$16128)-ROW($A$3)+1),ROWS(D$4:D8))),"")}
A9: {=IF(ROWS(A$4:A9)<=$B$2,INDEX(data!C$3:C$16128,SMALL(IF(data!$D$3:$D$16128=$B$1,ROW(data!$A$3:$A$16128)-ROW($A$3)+1),ROWS(A$4:A9))),"")} -> 46027 | B9: {=IF(ROWS(B$4:B9)<=$B$2,INDEX(data!A$3:A$16128,SMALL(IF(data!$D$3:$D$16128='Лозeнец'!$B$1,ROW(data!$A$3:$A$16128)-ROW($A$3)+1),ROWS(B$4:B9))),"")} -> MYPOS Бакалия | C9: {=IF(ROWS(C$4:C9)<=$B$2,INDEX(data!B$3:B$16128,SMALL(IF(data!$D$3:$D$16128='Лозeнец'!$B$1,ROW(data!$A$3:$A$16128)-ROW($A$3)+1),ROWS(C$4:C9))),"")} -> -5151.96 | D9: {=IF(ROWS(D$4:D9)<=$B$2,INDEX(data!E$3:E$16128,SMALL(IF(data!$D$3:$D$16128='Лозeнец'!$B$1,ROW(data!$A$3:$A$16128)-ROW($A$3)+1),ROWS(D$4:D9))),"")} -> 29-31,12
A10: {=IF(ROWS(A$4:A10)<=$B$2,INDEX(data!C$3:C$16128,SMALL(IF(data!$D$3:$D$16128=$B$1,ROW(data!$A$3:$A$16128)-ROW($A$3)+1),ROWS(A$4:A10))),"")} -> 46027 | B10: {=IF(ROWS(B$4:B10)<=$B$2,INDEX(data!A$3:A$16128,SMALL(IF(data!$D$3:$D$16128='Лозeнец'!$B$1,ROW(data!$A$3:$A$16128)-ROW($A$3)+1),ROWS(B$4:B10))),"")} -> КАСОВА КНИГА | C10: {=IF(ROWS(C$4:C10)<=$B$2,INDEX(data!B$3:B$16128,SMALL(IF(data!$D$3:$D$16128='Лозeнец'!$B$1,ROW(data!$A$3:$A$16128)-ROW($A$3)+1),ROWS(C$4:C10))),"")} -> 5665 | D10: {=IF(ROWS(D$4:D10)<=$B$2,INDEX(data!E$3:E$16128,SMALL(IF(data!$D$3:$D$16128='Лозeнец'!$B$1,ROW(data!$A$3:$A$16128)-ROW($A$3)+1),ROWS(D$4:D10))),"")} -> евро
A11: {=IF(ROWS(A$4:A11)<=$B$2,INDEX(data!C$3:C$16128,SMALL(IF(data!$D$3:$D$16128=$B$1,ROW(data!$A$3:$A$16128)-ROW($A$3)+1),ROWS(A$4:A11))),"")} -> 46028 | B11: {=IF(ROWS(B$4:B11)<=$B$2,INDEX(data!A$3:A$16128,SMALL(IF(data!$D$3:$D$16128='Лозeнец'!$B$1,ROW(data!$A$3:$A$16128)-ROW($A$3)+1),ROWS(B$4:B11))),"")} -> каса ФИКТИВНА | C11: {=IF(ROWS(C$4:C11)<=$B$2,INDEX(data!B$3:B$16128,SMALL(IF(data!$D$3:$D$16128='Лозeнец'!$B$1,ROW(data!$A$3:$A$16128)-ROW($A$3)+1),ROWS(C$4:C11))),"")} -> -350 | D11: {=IF(ROWS(D$4:D11)<=$B$2,INDEX(data!E$3:E$16128,SMALL(IF(data!$D$3:$D$16128='Лозeнец'!$B$1,ROW(data!$A$3:$A$16128)-ROW($A$3)+1),ROWS(D$4:D11))),"")} -> Мимето от премиите
A12: {=IF(ROWS(A$4:A12)<=$B$2,INDEX(data!C$3:C$16128,SMALL(IF(data!$D$3:$D$16128=$B$1,ROW(data!$A$3:$A$16128)-ROW($A$3)+1),ROWS(A$4:A12))),"")} -> 46029 | B12: {=IF(ROWS(B$4:B12)<=$B$2,INDEX(data!A$3:A$16128,SMALL(IF(data!$D$3:$D$16128='Лозeнец'!$B$1,ROW(data!$A$3:$A$16128)-ROW($A$3)+1),ROWS(B$4:B12))),"")} -> КАСОВА КНИГА | C12: {=IF(ROWS(C$4:C12)<=$B$2,INDEX(data!B$3:B$16128,SMALL(IF(data!$D$3:$D$16128='Лозeнец'!$B$1,ROW(data!$A$3:$A$16128)-ROW($A$3)+1),ROWS(C$4:C12))),"")} -> -2000 | D12: {=IF(ROWS(D$4:D12)<=$B$2,INDEX(data!E$3:E$16128,SMALL(IF(data!$D$3:$D$16128='Лозeнец'!$B$1,ROW(data!$A$3:$A$16128)-ROW($A$3)+1),ROWS(D$4:D12))),"")}
A13: {=IF(ROWS(A$4:A13)<=$B$2,INDEX(data!C$3:C$16128,SMALL(IF(data!$D$3:$D$16128=$B$1,ROW(data!$A$3:$A$16128)-ROW($A$3)+1),ROWS(A$4:A13))),"")} -> 46030 | B13: {=IF(ROWS(B$4:B13)<=$B$2,INDEX(data!A$3:A$16128,SMALL(IF(data!$D$3:$D$16128='Лозeнец'!$B$1,ROW(data!$A$3:$A$16128)-ROW($A$3)+1),ROWS(B$4:B13))),"")} -> КАСОВА КНИГА | C13: {=IF(ROWS(C$4:C13)<=$B$2,INDEX(data!B$3:B$16128,SMALL(IF(data!$D$3:$D$16128='Лозeнец'!$B$1,ROW(data!$A$3:$A$16128)-ROW($A$3)+1),ROWS(C$4:C13))),"")} -> -777 | D13: {=IF(ROWS(D$4:D13)<=$B$2,INDEX(data!E$3:E$16128,SMALL(IF(data!$D$3:$D$16128='Лозeнец'!$B$1,ROW(data!$A$3:$A$16128)-ROW($A$3)+1),ROWS(D$4:D13))),"")}
A14: {=IF(ROWS(A$4:A14)<=$B$2,INDEX(data!C$3:C$16128,SMALL(IF(data!$D$3:$D$16128=$B$1,ROW(data!$A$3:$A$16128)-ROW($A$3)+1),ROWS(A$4:A14))),"")} -> 46030 | B14: {=IF(ROWS(B$4:B14)<=$B$2,INDEX(data!A$3:A$16128,SMALL(IF(data!$D$3:$D$16128='Лозeнец'!$B$1,ROW(data!$A$3:$A$16128)-ROW($A$3)+1),ROWS(B$4:B14))),"")} -> Каса ВАУЧЕРИ | C14: {=IF(ROWS(C$4:C14)<=$B$2,INDEX(data!B$3:B$16128,SMALL(IF(data!$D$3:$D$16128='Лозeнец'!$B$1,ROW(data!$A$3:$A$16128)-ROW($A$3)+1),ROWS(C$4:C14))),"")} -> -7.16 | D14: {=IF(ROWS(D$4:D14)<=$B$2,INDEX(data!E$3:E$16128,SMALL(IF(data!$D$3:$D$16128='Лозeнец'!$B$1,ROW(data!$A$3:$A$16128)-ROW($A$3)+1),ROWS(D$4:D14))),"")} -> за 22.12
A15: {=IF(ROWS(A$4:A15)<=$B$2,INDEX(data!C$3:C$16128,SMALL(IF(data!$D$3:$D$16128=$B$1,ROW(data!$A$3:$A$16128)-ROW($A$3)+1),ROWS(A$4:A15))),"")} -> 46031 | B15: {=IF(ROWS(B$4:B15)<=$B$2,INDEX(data!A$3:A$16128,SMALL(IF(data!$D$3:$D$16128='Лозeнец'!$B$1,ROW(data!$A$3:$A$16128)-ROW($A$3)+1),ROWS(B$4:B15))),"")} -> КАСОВА КНИГА | C15: {=IF(ROWS(C$4:C15)<=$B$2,INDEX(data!B$3:B$16128,SMALL(IF(data!$D$3:$D$16128='Лозeнец'!$B$1,ROW(data!$A$3:$A$16128)-ROW($A$3)+1),ROWS(C$4:C15))),"")} -> -2000 | D15: {=IF(ROWS(D$4:D15)<=$B$2,INDEX(data!E$3:E$16128,SMALL(IF(data!$D$3:$D$16128='Лозeнец'!$B$1,ROW(data!$A$3:$A$16128)-ROW($A$3)+1),ROWS(D$4:D15))),"")}
... A171: {=IF(ROWS(A$4:A171)<=$B$2,INDEX(data!C$3:C$16128,SMALL(IF(data!$D$3:$D$16128=$B$1,ROW(data!$A$3:$A$16128)-ROW($A$3)+1),ROWS(A$4:A171))),"")} | B171: {=IF(ROWS(B$4:B171)<=$B$2,INDEX(data!A$3:A$16128,SMALL(IF(data!$D$3:$D$16128='Лозeнец'!$B$1,ROW(data!$A$3:$A$16128)-ROW($A$3)+1),ROWS(B$4:B171))),"")} | C171: {=IF(ROWS(C$4:C171)<=$B$2,INDEX(data!B$3:B$16128,SMALL(IF(data!$D$3:$D$16128='Лозeнец'!$B$1,ROW(data!$A$3:$A$16128)-ROW($A$3)+1),ROWS(C$4:C171))),"")} | D171: {=IF(ROWS(D$4:D171)<=$B$2,INDEX(data!E$3:E$16128,SMALL(IF(data!$D$3:$D$16128='Лозeнец'!$B$1,ROW(data!$A$3:$A$16128)-ROW($A$3)+1),ROWS(D$4:D171))),"")}

Sheet Люлин
A1: Обект | B1: СМ Люлин | E1: C:C | F1: =SUM(C:C) -> -51661.014 | G1: 03,01,2026/11,15ч
A2: Брой съвпадения | B2: =COUNTIF(data!D:D,B1) -> 303 | E2: Начално с-до | F2: 114717.43
A3: Дата | B3: Артикул | C3: Стойност | D3: Забележка | E3: САЛДО | F3: =F1+F2 -> 63056.416
A4: {=IF(ROWS(A$4:A4)<=$B$2,INDEX(data!C$3:C$16128,SMALL(IF(data!$D$3:$D$16128='Люлин'!$B$1,ROW(data!$A$3:$A$16128)-ROW($A$3)+1),ROWS(A$4:A4))),"")} -> 44557 | B4: {=IF(ROWS(B$4:B4)<=$B$2,INDEX(data!A$3:A$16128,SMALL(IF(data!$D$3:$D$16128='Люлин'!$B$1,ROW(data!$A$3:$A$16128)-ROW($A$3)+1),ROWS(B$4:B4))),"")} -> MYPOS Бакалия | C4: {=IF(ROWS(C$4:C4)<=$B$2,INDEX(data!B$3:B$16128,SMALL(IF(data!$D$3:$D$16128='Люлин'!$B$1,ROW(data!$A$3:$A$16128)-ROW($A$3)+1),ROWS(C$4:C4))),"")} -> -0.01 | D4: {=IF(ROWS(D$4:D4)<=$B$2,INDEX(data!E$3:E$16128,SMALL(IF(data!$D$3:$D$16128='Люлин'!$B$1,ROW(data!$A$3:$A$16128)-ROW($A$3)+1),ROWS(D$4:D4))),"")}
A5: {=IF(ROWS(A$4:A5)<=$B$2,INDEX(data!C$3:C$16128,SMALL(IF(data!$D$3:$D$16128='Люлин'!$B$1,ROW(data!$A$3:$A$16128)-ROW($A$3)+1),ROWS(A$4:A5))),"")} -> 46025 | B5: {=IF(ROWS(B$4:B5)<=$B$2,INDEX(data!A$3:A$16128,SMALL(IF(data!$D$3:$D$16128='Люлин'!$B$1,ROW(data!$A$3:$A$16128)-ROW($A$3)+1),ROWS(B$4:B5))),"")} -> ЗАЕМ | C5: {=IF(ROWS(C$4:C5)<=$B$2,INDEX(data!B$3:B$16128,SMALL(IF(data!$D$3:$D$16128='Люлин'!$B$1,ROW(data!$A$3:$A$16128)-ROW($A$3)+1),ROWS(C$4:C5))),"")} -> 17370.17 | D5: {=IF(ROWS(D$4:D5)<=$B$2,INDEX(data!E$3:E$16128,SMALL(IF(data!$D$3:$D$16128='Люлин'!$B$1,ROW(data!$A$3:$A$16128)-ROW($A$3)+1),ROWS(D$4:D5))),"")} -> Салдо скл + вътр. п-не
A6: {=IF(ROWS(A$4:A6)<=$B$2,INDEX(data!C$3:C$16128,SMALL(IF(data!$D$3:$D$16128='Люлин'!$B$1,ROW(data!$A$3:$A$16128)-ROW($A$3)+1),ROWS(A$4:A6))),"")} -> 46027 | B6: {=IF(ROWS(B$4:B6)<=$B$2,INDEX(data!A$3:A$16128,SMALL(IF(data!$D$3:$D$16128='Люлин'!$B$1,ROW(data!$A$3:$A$16128)-ROW($A$3)+1),ROWS(B$4:B6))),"")} -> КАСОВА КНИГА | C6: {=IF(ROWS(C$4:C6)<=$B$2,INDEX(data!B$3:B$16128,SMALL(IF(data!$D$3:$D$16128='Люлин'!$B$1,ROW(data!$A$3:$A$16128)-ROW($A$3)+1),ROWS(C$4:C6))),"")} -> -3834.69 | D6: {=IF(ROWS(D$4:D6)<=$B$2,INDEX(data!E$3:E$16128,SMALL(IF(data!$D$3:$D$16128='Люлин'!$B$1,ROW(data!$A$3:$A$16128)-ROW($A$3)+1),ROWS(D$4:D6))),"")} -> банка 02.01
A7: {=IF(ROWS(A$4:A7)<=$B$2,INDEX(data!C$3:C$16128,SMALL(IF(data!$D$3:$D$16128='Люлин'!$B$1,ROW(data!$A$3:$A$16128)-ROW($A$3)+1),ROWS(A$4:A7))),"")} -> 46027 | B7: {=IF(ROWS(B$4:B7)<=$B$2,INDEX(data!A$3:A$16128,SMALL(IF(data!$D$3:$D$16128='Люлин'!$B$1,ROW(data!$A$3:$A$16128)-ROW($A$3)+1),ROWS(B$4:B7))),"")} -> MYPOS Бакалия | C7: {=IF(ROWS(C$4:C7)<=$B$2,INDEX(data!B$3:B$16128,SMALL(IF(data!$D$3:$D$16128='Люлин'!$B$1,ROW(data!$A$3:$A$16128)-ROW($A$3)+1),ROWS(C$4:C7))),"")} -> -1896.62 | D7: {=IF(ROWS(D$4:D7)<=$B$2,INDEX(data!E$3:E$16128,SMALL(IF(data!$D$3:$D$16128='Люлин'!$B$1,ROW(data!$A$3:$A$16128)-ROW($A$3)+1),ROWS(D$4:D7))),"")}
A8: {=IF(ROWS(A$4:A8)<=$B$2,INDEX(data!C$3:C$16128,SMALL(IF(data!$D$3:$D$16128='Люлин'!$B$1,ROW(data!$A$3:$A$16128)-ROW($A$3)+1),ROWS(A$4:A8))),"")} -> 46027 | B8: {=IF(ROWS(B$4:B8)<=$B$2,INDEX(data!A$3:A$16128,SMALL(IF(data!$D$3:$D$16128='Люлин'!$B$1,ROW(data!$A$3:$A$16128)-ROW($A$3)+1),ROWS(B$4:B8))),"")} -> КАСОВА КНИГА | C8: {=IF(ROWS(C$4:C8)<=$B$2,INDEX(data!B$3:B$16128,SMALL(IF(data!$D$3:$D$16128='Люлин'!$B$1,ROW(data!$A$3:$A$16128)-ROW($A$3)+1),ROWS(C$4:C8))),"")} -> -2556.46 | D8: {=IF(ROWS(D$4:D8)<=$B$2,INDEX(data!E$3:E$16128,SMALL(IF(data!$D$3:$D$16128='Люлин'!$B$1,ROW(data!$A$3:$A$16128)-ROW($A$3)+1),ROWS(D$4:D8))),"")}
A9: {=IF(ROWS(A$4:A9)<=$B$2,INDEX(data!C$3:C$16128,SMALL(IF(data!$D$3:$D$16128='Люлин'!$B$1,ROW(data!$A$3:$A$16128)-ROW($A$3)+1),ROWS(A$4:A9))),"")} -> 46027 | B9: {=IF(ROWS(B$4:B9)<=$B$2,INDEX(data!A$3:A$16128,SMALL(IF(data!$D$3:$D$16128='Люлин'!$B$1,ROW(data!$A$3:$A$16128)-ROW($A$3)+1),ROWS(B$4:B9))),"")} -> MYPOS Бакалия | C9: {=IF(ROWS(C$4:C9)<=$B$2,INDEX(data!B$3:B$16128,SMALL(IF(data!$D$3:$D$16128='Люлин'!$B$1,ROW(data!$A$3:$A$16128)-ROW($A$3)+1),ROWS(C$4:C9))),"")} -> -3375.12 | D9: {=IF(ROWS(D$4:D9)<=$B$2,INDEX(data!E$3:E$16128,SMALL(IF(data!$D$3:$D$16128='Люлин'!$B$1,ROW(data!$A$3:$A$16128)-ROW($A$3)+1),ROWS(D$4:D9))),"")} -> 29-31,12
A10: {=IF(ROWS(A$4:A10)<=$B$2,INDEX(data!C$3:C$16128,SMALL(IF(data!$D$3:$D$16128='Люлин'!$B$1,ROW(data!$A$3:$A$16128)-ROW($A$3)+1),ROWS(A$4:A10))),"")} -> 46027 | B10: {=IF(ROWS(B$4:B10)<=$B$2,INDEX(data!A$3:A$16128,SMALL(IF(data!$D$3:$D$16128='Люлин'!$B$1,ROW(data!$A$3:$A$16128)-ROW($A$3)+1),ROWS(B$4:B10))),"")} -> КАСОВА КНИГА | C10: {=IF(ROWS(C$4:C10)<=$B$2,INDEX(data!B$3:B$16128,SMALL(IF(data!$D$3:$D$16128='Люлин'!$B$1,ROW(data!$A$3:$A$16128)-ROW($A$3)+1),ROWS(C$4:C10))),"")} -> 7554 | D10: {=IF(ROWS(D$4:D10)<=$B$2,INDEX(data!E$3:E$16128,SMALL(IF(data!$D$3:$D$16128='Люлин'!$B$1,ROW(data!$A$3:$A$16128)-ROW($A$3)+1),ROWS(D$4:D10))),"")} -> евро
A11: {=IF(ROWS(A$4:A11)<=$B$2,INDEX(data!C$3:C$16128,SMALL(IF(data!$D$3:$D$16128='Люлин'!$B$1,ROW(data!$A$3:$A$16128)-ROW($A$3)+1),ROWS(A$4:A11))),"")} -> 46028 | B11: {=IF(ROWS(B$4:B11)<=$B$2,INDEX(data!A$3:A$16128,SMALL(IF(data!$D$3:$D$16128='Люлин'!$B$1,ROW(data!$A$3:$A$16128)-ROW($A$3)+1),ROWS(B$4:B11))),"")} -> КАСОВА КНИГА | C11: {=IF(ROWS(C$4:C11)<=$B$2,INDEX(data!B$3:B$16128,SMALL(IF(data!$D$3:$D$16128='Люлин'!$B$1,ROW(data!$A$3:$A$16128)-ROW($A$3)+1),ROWS(C$4:C11))),"")} -> -1022.58 | D11: {=IF(ROWS(D$4:D11)<=$B$2,INDEX(data!E$3:E$16128,SMALL(IF(data!$D$3:$D$16128='Люлин'!$B$1,ROW(data!$A$3:$A$16128)-ROW($A$3)+1),ROWS(D$4:D11))),"")}
A12: {=IF(ROWS(A$4:A12)<=$B$2,INDEX(data!C$3:C$16128,SMALL(IF(data!$D$3:$D$16128='Люлин'!$B$1,ROW(data!$A$3:$A$16128)-ROW($A$3)+1),ROWS(A$4:A12))),"")} -> 46028 | B12: {=IF(ROWS(B$4:B12)<=$B$2,INDEX(data!A$3:A$16128,SMALL(IF(data!$D$3:$D$16128='Люлин'!$B$1,ROW(data!$A$3:$A$16128)-ROW($A$3)+1),ROWS(B$4:B12))),"")} -> каса ФИКТИВНА | C12: {=IF(ROWS(C$4:C12)<=$B$2,INDEX(data!B$3:B$16128,SMALL(IF(data!$D$3:$D$16128='Люлин'!$B$1,ROW(data!$A$3:$A$16128)-ROW($A$3)+1),ROWS(C$4:C12))),"")} -> -200 | D12: {=IF(ROWS(D$4:D12)<=$B$2,INDEX(data!E$3:E$16128,SMALL(IF(data!$D$3:$D$16128='Люлин'!$B$1,ROW(data!$A$3:$A$16128)-ROW($A$3)+1),ROWS(D$4:D12))),"")} -> Спартак от премиите
A13: {=IF(ROWS(A$4:A13)<=$B$2,INDEX(data!C$3:C$16128,SMALL(IF(data!$D$3:$D$16128='Люлин'!$B$1,ROW(data!$A$3:$A$16128)-ROW($A$3)+1),ROWS(A$4:A13))),"")} -> 46029 | B13: {=IF(ROWS(B$4:B13)<=$B$2,INDEX(data!A$3:A$16128,SMALL(IF(data!$D$3:$D$16128='Люлин'!$B$1,ROW(data!$A$3:$A$16128)-ROW($A$3)+1),ROWS(B$4:B13))),"")} -> КАСОВА КНИГА | C13: {=IF(ROWS(C$4:C13)<=$B$2,INDEX(data!B$3:B$16128,SMALL(IF(data!$D$3:$D$16128='Люлин'!$B$1,ROW(data!$A$3:$A$16128)-ROW($A$3)+1),ROWS(C$4:C13))),"")} -> -511.29 | D13: {=IF(ROWS(D$4:D13)<=$B$2,INDEX(data!E$3:E$16128,SMALL(IF(data!$D$3:$D$16128='Люлин'!$B$1,ROW(data!$A$3:$A$16128)-ROW($A$3)+1),ROWS(D$4:D13))),"")}
A14: {=IF(ROWS(A$4:A14)<=$B$2,INDEX(data!C$3:C$16128,SMALL(IF(data!$D$3:$D$16128='Люлин'!$B$1,ROW(data!$A$3:$A$16128)-ROW($A$3)+1),ROWS(A$4:A14))),"")} -> 46029 | B14: {=IF(ROWS(B$4:B14)<=$B$2,INDEX(data!A$3:A$16128,SMALL(IF(data!$D$3:$D$16128='Люлин'!$B$1,ROW(data!$A$3:$A$16128)-ROW($A$3)+1),ROWS(B$4:B14))),"")} -> каса ФИКТИВНА | C14: {=IF(ROWS(C$4:C14)<=$B$2,INDEX(data!B$3:B$16128,SMALL(IF(data!$D$3:$D$16128='Люлин'!$B$1,ROW(data!$A$3:$A$16128)-ROW($A$3)+1),ROWS(C$4:C14))),"")} -> -75 | D14: {=IF(ROWS(D$4:D14)<=$B$2,INDEX(data!E$3:E$16128,SMALL(IF(data!$D$3:$D$16128='Люлин'!$B$1,ROW(data!$A$3:$A$16128)-ROW($A$3)+1),ROWS(D$4:D14))),"")} -> пазар Тихомир
A15: {=IF(ROWS(A$4:A15)<=$B$2,INDEX(data!C$3:C$16128,SMALL(IF(data!$D$3:$D$16128='Люлин'!$B$1,ROW(data!$A$3:$A$16128)-ROW($A$3)+1),ROWS(A$4:A15))),"")} -> 46030 | B15: {=IF(ROWS(B$4:B15)<=$B$2,INDEX(data!A$3:A$16128,SMALL(IF(data!$D$3:$D$16128='Люлин'!$B$1,ROW(data!$A$3:$A$16128)-ROW($A$3)+1),ROWS(B$4:B15))),"")} -> КАСОВА КНИГА | C15: {=IF(ROWS(C$4:C15)<=$B$2,INDEX(data!B$3:B$16128,SMALL(IF(data!$D$3:$D$16128='Люлин'!$B$1,ROW(data!$A$3:$A$16128)-ROW($A$3)+1),ROWS(C$4:C15))),"")} -> -511.29 | D15: {=IF(ROWS(D$4:D15)<=$B$2,INDEX(data!E$3:E$16128,SMALL(IF(data!$D$3:$D$16128='Люлин'!$B$1,ROW(data!$A$3:$A$16128)-ROW($A$3)+1),ROWS(D$4:D15))),"")}
... A310: {=IF(ROWS(A$4:A310)<=$B$2,INDEX(data!C$3:C$16128,SMALL(IF(data!$D$3:$D$16128='Люлин'!$B$1,ROW(data!$A$3:$A$16128)-ROW($A$3)+1),ROWS(A$4:A310))),"")} | B310: {=IF(ROWS(B$4:B310)<=$B$2,INDEX(data!A$3:A$16128,SMALL(IF(data!$D$3:$D$16128='Люлин'!$B$1,ROW(data!$A$3:$A$16128)-ROW($A$3)+1),ROWS(B$4:B310))),"")} | C310: {=IF(ROWS(C$4:C310)<=$B$2,INDEX(data!B$3:B$16128,SMALL(IF(data!$D$3:$D$16128='Люлин'!$B$1,ROW(data!$A$3:$A$16128)-ROW($A$3)+1),ROWS(C$4:C310))),"")} | D310: {=IF(ROWS(D$4:D310)<=$B$2,INDEX(data!E$3:E$16128,SMALL(IF(data!$D$3:$D$16128='Люлин'!$B$1,ROW(data!$A$3:$A$16128)-ROW($A$3)+1),ROWS(D$4:D310))),"")}

Sheet Манастирски
A1: Обект | B1: СМ МАНАСТИРСКИ ЛИВАДИ | E1: C:C | F1: =SUM(C:C) -> -19601.589 | G1: 03,01,2026/11,15ч
A2: Брой съвпадения | B2: =COUNTIF(data!D:D,B1) -> 115 | E2: Начално с-до | F2: 88852.23
A3: Дата | B3: Артикул | C3: Стойност | D3: Забележка | E3: САЛДО | F3: =F1+F2 -> 69250.641
A4: {=IF(ROWS(A$4:A4)<=$B$2,INDEX(data!C$3:C$16128,SMALL(IF(data!$D$3:$D$16128='Манастирски'!$B$1,ROW(data!$A$3:$A$16128)-ROW($A$3)+1),ROWS(A$4:A4))),"")} -> 44557 | B4: {=IF(ROWS(B$4:B4)<=$B$2,INDEX(data!A$3:A$16128,SMALL(IF(data!$D$3:$D$16128='Манастирски'!$B$1,ROW(data!$A$3:$A$16128)-ROW($A$3)+1),ROWS(B$4:B4))),"")} -> MYPOS Бакалия | C4: {=IF(ROWS(C$4:C4)<=$B$2,INDEX(data!B$3:B$16128,SMALL(IF(data!$D$3:$D$16128='Манастирски'!$B$1,ROW(data!$A$3:$A$16128)-ROW($A$3)+1),ROWS(C$4:C4))),"")} -> -0.01 | D4: {=IF(ROWS(D$4:D4)<=$B$2,INDEX(data!E$3:E$16128,SMALL(IF(data!$D$3:$D$16128='Манастирски'!$B$1,ROW(data!$A$3:$A$16128)-ROW($A$3)+1),ROWS(D$4:D4))),"")}
A5: {=IF(ROWS(A$4:A5)<=$B$2,INDEX(data!C$3:C$16128,SMALL(IF(data!$D$3:$D$16128='Манастирски'!$B$1,ROW(data!$A$3:$A$16128)-ROW($A$3)+1),ROWS(A$4:A5))),"")} -> 46025 | B5: {=IF(ROWS(B$4:B5)<=$B$2,INDEX(data!A$3:A$16128,SMALL(IF(data!$D$3:$D$16128='Манастирски'!$B$1,ROW(data!$A$3:$A$16128)-ROW($A$3)+1),ROWS(B$4:B5))),"")} -> ЗАЕМ | C5: {=IF(ROWS(C$4:C5)<=$B$2,INDEX(data!B$3:B$16128,SMALL(IF(data!$D$3:$D$16128='Манастирски'!$B$1,ROW(data!$A$3:$A$16128)-ROW($A$3)+1),ROWS(C$4:C5))),"")} -> 7756.37 | D5: {=IF(ROWS(D$4:D5)<=$B$2,INDEX(data!E$3:E$16128,SMALL(IF(data!$D$3:$D$16128='Манастирски'!$B$1,ROW(data!$A$3:$A$16128)-ROW($A$3)+1),ROWS(D$4:D5))),"")} -> Салдо скл + вътр. п-не
A6: {=IF(ROWS(A$4:A6)<=$B$2,INDEX(data!C$3:C$16128,SMALL(IF(data!$D$3:$D$16128='Манастирски'!$B$1,ROW(data!$A$3:$A$16128)-ROW($A$3)+1),ROWS(A$4:A6))),"")} -> 46027 | B6: {=IF(ROWS(B$4:B6)<=$B$2,INDEX(data!A$3:A$16128,SMALL(IF(data!$D$3:$D$16128='Манастирски'!$B$1,ROW(data!$A$3:$A$16128)-ROW($A$3)+1),ROWS(B$4:B6))),"")} -> КАСОВА КНИГА | C6: {=IF(ROWS(C$4:C6)<=$B$2,INDEX(data!B$3:B$16128,SMALL(IF(data!$D$3:$D$16128='Манастирски'!$B$1,ROW(data!$A$3:$A$16128)-ROW($A$3)+1),ROWS(C$4:C6))),"")} -> -511.29 | D6: {=IF(ROWS(D$4:D6)<=$B$2,INDEX(data!E$3:E$16128,SMALL(IF(data!$D$3:$D$16128='Манастирски'!$B$1,ROW(data!$A$3:$A$16128)-ROW($A$3)+1),ROWS(D$4:D6))),"")} -> банка 02.01
A7: {=IF(ROWS(A$4:A7)<=$B$2,INDEX(data!C$3:C$16128,SMALL(IF(data!$D$3:$D$16128='Манастирски'!$B$1,ROW(data!$A$3:$A$16128)-ROW($A$3)+1),ROWS(A$4:A7))),"")} -> 46027 | B7: {=IF(ROWS(B$4:B7)<=$B$2,INDEX(data!A$3:A$16128,SMALL(IF(data!$D$3:$D$16128='Манастирски'!$B$1,ROW(data!$A$3:$A$16128)-ROW($A$3)+1),ROWS(B$4:B7))),"")} -> MYPOS Бакалия | C7: {=IF(ROWS(C$4:C7)<=$B$2,INDEX(data!B$3:B$16128,SMALL(IF(data!$D$3:$D$16128='Манастирски'!$B$1,ROW(data!$A$3:$A$16128)-ROW($A$3)+1),ROWS(C$4:C7))),"")} -> -2263.17 | D7: {=IF(ROWS(D$4:D7)<=$B$2,INDEX(data!E$3:E$16128,SMALL(IF(data!$D$3:$D$16128='Манастирски'!$B$1,ROW(data!$A$3:$A$16128)-ROW($A$3)+1),ROWS(D$4:D7))),"")}
A8: {=IF(ROWS(A$4:A8)<=$B$2,INDEX(data!C$3:C$16128,SMALL(IF(data!$D$3:$D$16128='Манастирски'!$B$1,ROW(data!$A$3:$A$16128)-ROW($A$3)+1),ROWS(A$4:A8))),"")} -> 46027 | B8: {=IF(ROWS(B$4:B8)<=$B$2,INDEX(data!A$3:A$16128,SMALL(IF(data!$D$3:$D$16128='Манастирски'!$B$1,ROW(data!$A$3:$A$16128)-ROW($A$3)+1),ROWS(B$4:B8))),"")} -> КАСОВА КНИГА | C8: {=IF(ROWS(C$4:C8)<=$B$2,INDEX(data!B$3:B$16128,SMALL(IF(data!$D$3:$D$16128='Манастирски'!$B$1,ROW(data!$A$3:$A$16128)-ROW($A$3)+1),ROWS(C$4:C8))),"")} -> -1022.58 | D8: {=IF(ROWS(D$4:D8)<=$B$2,INDEX(data!E$3:E$16128,SMALL(IF(data!$D$3:$D$16128='Манастирски'!$B$1,ROW(data!$A$3:$A$16128)-ROW($A$3)+1),ROWS(D$4:D8))),"")}
A9: {=IF(ROWS(A$4:A9)<=$B$2,INDEX(data!C$3:C$16128,SMALL(IF(data!$D$3:$D$16128='Манастирски'!$B$1,ROW(data!$A$3:$A$16128)-ROW($A$3)+1),ROWS(A$4:A9))),"")} -> 46027 | B9: {=IF(ROWS(B$4:B9)<=$B$2,INDEX(data!A$3:A$16128,SMALL(IF(data!$D$3:$D$16128='Манастирски'!$B$1,ROW(data!$A$3:$A$16128)-ROW($A$3)+1),ROWS(B$4:B9))),"")} -> MYPOS Бакалия | C9: {=IF(ROWS(C$4:C9)<=$B$2,INDEX(data!B$3:B$16128,SMALL(IF(data!$D$3:$D$16128='Манастирски'!$B$1,ROW(data!$A$3:$A$16128)-ROW($A$3)+1),ROWS(C$4:C9))),"")} -> -1649.87 | D9: {=IF(ROWS(D$4:D9)<=$B$2,INDEX(data!E$3:E$16128,SMALL(IF(data!$D$3:$D$16128='Манастирски'!$B$1,ROW(data!$A$3:$A$16128)-ROW($A$3)+1),ROWS(D$4:D9))),"")} -> 29-31,12
A10: {=IF(ROWS(A$4:A10)<=$B$2,INDEX(data!C$3:C$16128,SMALL(IF(data!$D$3:$D$16128='Манастирски'!$B$1,ROW(data!$A$3:$A$16128)-ROW($A$3)+1),ROWS(A$4:A10))),"")} -> 46027 | B10: {=IF(ROWS(B$4:B10)<=$B$2,INDEX(data!A$3:A$16128,SMALL(IF(data!$D$3:$D$16128='Манастирски'!$B$1,ROW(data!$A$3:$A$16128)-ROW($A$3)+1),ROWS(B$4:B10))),"")} -> КАСОВА КНИГА | C10: {=IF(ROWS(C$4:C10)<=$B$2,INDEX(data!B$3:B$16128,SMALL(IF(data!$D$3:$D$16128='Манастирски'!$B$1,ROW(data!$A$3:$A$16128)-ROW($A$3)+1),ROWS(C$4:C10))),"")} -> 3110 | D10: {=IF(ROWS(D$4:D10)<=$B$2,INDEX(data!E$3:E$16128,SMALL(IF(data!$D$3:$D$16128='Манастирски'!$B$1,ROW(data!$A$3:$A$16128)-ROW($A$3)+1),ROWS(D$4:D10))),"")} -> евро
A11: {=IF(ROWS(A$4:A11)<=$B$2,INDEX(data!C$3:C$16128,SMALL(IF(data!$D$3:$D$16128='Манастирски'!$B$1,ROW(data!$A$3:$A$16128)-ROW($A$3)+1),ROWS(A$4:A11))),"")} -> 46029 | B11: {=IF(ROWS(B$4:B11)<=$B$2,INDEX(data!A$3:A$16128,SMALL(IF(data!$D$3:$D$16128='Манастирски'!$B$1,ROW(data!$A$3:$A$16128)-ROW($A$3)+1),ROWS(B$4:B11))),"")} -> каса ФИКТИВНА | C11: {=IF(ROWS(C$4:C11)<=$B$2,INDEX(data!B$3:B$16128,SMALL(IF(data!$D$3:$D$16128='Манастирски'!$B$1,ROW(data!$A$3:$A$16128)-ROW($A$3)+1),ROWS(C$4:C11))),"")} -> -260 | D11: {=IF(ROWS(D$4:D11)<=$B$2,INDEX(data!E$3:E$16128,SMALL(IF(data!$D$3:$D$16128='Манастирски'!$B$1,ROW(data!$A$3:$A$16128)-ROW($A$3)+1),ROWS(D$4:D11))),"")} -> Краси от премиите
A12: {=IF(ROWS(A$4:A12)<=$B$2,INDEX(data!C$3:C$16128,SMALL(IF(data!$D$3:$D$16128='Манастирски'!$B$1,ROW(data!$A$3:$A$16128)-ROW($A$3)+1),ROWS(A$4:A12))),"")} -> 46034 | B12: {=IF(ROWS(B$4:B12)<=$B$2,INDEX(data!A$3:A$16128,SMALL(IF(data!$D$3:$D$16128='Манастирски'!$B$1,ROW(data!$A$3:$A$16128)-ROW($A$3)+1),ROWS(B$4:B12))),"")} -> КАСОВА КНИГА | C12: {=IF(ROWS(C$4:C12)<=$B$2,INDEX(data!B$3:B$16128,SMALL(IF(data!$D$3:$D$16128='Манастирски'!$B$1,ROW(data!$A$3:$A$16128)-ROW($A$3)+1),ROWS(C$4:C12))),"")} -> -1000.65 | D12: {=IF(ROWS(D$4:D12)<=$B$2,INDEX(data!E$3:E$16128,SMALL(IF(data!$D$3:$D$16128='Манастирски'!$B$1,ROW(data!$A$3:$A$16128)-ROW($A$3)+1),ROWS(D$4:D12))),"")}
A13: {=IF(ROWS(A$4:A13)<=$B$2,INDEX(data!C$3:C$16128,SMALL(IF(data!$D$3:$D$16128='Манастирски'!$B$1,ROW(data!$A$3:$A$16128)-ROW($A$3)+1),ROWS(A$4:A13))),"")} -> 46035 | B13: {=IF(ROWS(B$4:B13)<=$B$2,INDEX(data!A$3:A$16128,SMALL(IF(data!$D$3:$D$16128='Манастирски'!$B$1,ROW(data!$A$3:$A$16128)-ROW($A$3)+1),ROWS(B$4:B13))),"")} -> MYPOS Бакалия | C13: {=IF(ROWS(C$4:C13)<=$B$2,INDEX(data!B$3:B$16128,SMALL(IF(data!$D$3:$D$16128='Манастирски'!$B$1,ROW(data!$A$3:$A$16128)-ROW($A$3)+1),ROWS(C$4:C13))),"")} -> -4456.32 | D13: {=IF(ROWS(D$4:D13)<=$B$2,INDEX(data!E$3:E$16128,SMALL(IF(data!$D$3:$D$16128='Манастирски'!$B$1,ROW(data!$A$3:$A$16128)-ROW($A$3)+1),ROWS(D$4:D13))),"")}
A14: {=IF(ROWS(A$4:A14)<=$B$2,INDEX(data!C$3:C$16128,SMALL(IF(data!$D$3:$D$16128='Манастирски'!$B$1,ROW(data!$A$3:$A$16128)-ROW($A$3)+1),ROWS(A$4:A14))),"")} -> 46036 | B14: {=IF(ROWS(B$4:B14)<=$B$2,INDEX(data!A$3:A$16128,SMALL(IF(data!$D$3:$D$16128='Манастирски'!$B$1,ROW(data!$A$3:$A$16128)-ROW($A$3)+1),ROWS(B$4:B14))),"")} -> КАСОВА КНИГА | C14: {=IF(ROWS(C$4:C14)<=$B$2,INDEX(data!B$3:B$16128,SMALL(IF(data!$D$3:$D$16128='Манастирски'!$B$1,ROW(data!$A$3:$A$16128)-ROW($A$3)+1),ROWS(C$4:C14))),"")} -> -600 | D14: {=IF(ROWS(D$4:D14)<=$B$2,INDEX(data!E$3:E$16128,SMALL(IF(data!$D$3:$D$16128='Манастирски'!$B$1,ROW(data!$A$3:$A$16128)-ROW($A$3)+1),ROWS(D$4:D14))),"")}
A15: {=IF(ROWS(A$4:A15)<=$B$2,INDEX(data!C$3:C$16128,SMALL(IF(data!$D$3:$D$16128='Манастирски'!$B$1,ROW(data!$A$3:$A$16128)-ROW($A$3)+1),ROWS(A$4:A15))),"")} -> 46038 | B15: {=IF(ROWS(B$4:B15)<=$B$2,INDEX(data!A$3:A$16128,SMALL(IF(data!$D$3:$D$16128='Манастирски'!$B$1,ROW(data!$A$3:$A$16128)-ROW($A$3)+1),ROWS(B$4:B15))),"")} -> КАСОВА КНИГА | C15: {=IF(ROWS(C$4:C15)<=$B$2,INDEX(data!B$3:B$16128,SMALL(IF(data!$D$3:$D$16128='Манастирски'!$B$1,ROW(data!$A$3:$A$16128)-ROW($A$3)+1),ROWS(C$4:C15))),"")} -> -255.65 | D15: {=IF(ROWS(D$4:D15)<=$B$2,INDEX(data!E$3:E$16128,SMALL(IF(data!$D$3:$D$16128='Манастирски'!$B$1,ROW(data!$A$3:$A$16128)-ROW($A$3)+1),ROWS(D$4:D15))),"")}
... A125: {=IF(ROWS(A$4:A125)<=$B$2,INDEX(data!C$3:C$16128,SMALL(IF(data!$D$3:$D$16128='Манастирски'!$B$1,ROW(data!$A$3:$A$16128)-ROW($A$3)+1),ROWS(A$4:A125))),"")} | B125: {=IF(ROWS(B$4:B125)<=$B$2,INDEX(data!A$3:A$16128,SMALL(IF(data!$D$3:$D$16128='Манастирски'!$B$1,ROW(data!$A$3:$A$16128)-ROW($A$3)+1),ROWS(B$4:B125))),"")} | C125: {=IF(ROWS(C$4:C125)<=$B$2,INDEX(data!B$3:B$16128,SMALL(IF(data!$D$3:$D$16128='Манастирски'!$B$1,ROW(data!$A$3:$A$16128)-ROW($A$3)+1),ROWS(C$4:C125))),"")} | D125: {=IF(ROWS(D$4:D125)<=$B$2,INDEX(data!E$3:E$16128,SMALL(IF(data!$D$3:$D$16128='Манастирски'!$B$1,ROW(data!$A$3:$A$16128)-ROW($A$3)+1),ROWS(D$4:D125))),"")}

Sheet Надежда
A1: Обект | B1: СМ Надежда | E1: C:C | F1: =SUM(C:C) -> -30020.446 | G1: 03,01,2026/11,15ч
A2: Брой съвпадения | B2: =COUNTIF(data!D:D,B1) -> 200 | E2: Начално с-до: | F2: 142580.75
A3: Дата | B3: Артикул | C3: Стойност | D3: Забележка | E3: САЛДО: | F3: =F1+F2 -> 112560.3
A4: {=IF(ROWS(A$4:A4)<=$B$2,INDEX(data!C$3:C$16128,SMALL(IF(data!$D$3:$D$16128='Надежда'!$B$1,ROW(data!$A$3:$A$16128)-ROW($A$3)+1),ROWS(A$4:A4))),"")} -> 44557 | B4: {=IF(ROWS(B$4:B4)<=$B$2,INDEX(data!A$3:A$16128,SMALL(IF(data!$D$3:$D$16128='Надежда'!$B$1,ROW(data!$A$3:$A$16128)-ROW($A$3)+1),ROWS(B$4:B4))),"")} -> MYPOS Бакалия | C4: {=IF(ROWS(C$4:C4)<=$B$2,INDEX(data!B$3:B$16128,SMALL(IF(data!$D$3:$D$16128='Надежда'!$B$1,ROW(data!$A$3:$A$16128)-ROW($A$3)+1),ROWS(C$4:C4))),"")} -> -0.01 | D4: {=IF(ROWS(D$4:D4)<=$B$2,INDEX(data!E$3:E$16128,SMALL(IF(data!$D$3:$D$16128='Надежда'!$B$1,ROW(data!$A$3:$A$16128)-ROW($A$3)+1),ROWS(D$4:D4))),"")}
A5: {=IF(ROWS(A$4:A5)<=$B$2,INDEX(data!C$3:C$16128,SMALL(IF(data!$D$3:$D$16128='Надежда'!$B$1,ROW(data!$A$3:$A$16128)-ROW($A$3)+1),ROWS(A$4:A5))),"")} -> 46025 | B5: {=IF(ROWS(B$4:B5)<=$B$2,INDEX(data!A$3:A$16128,SMALL(IF(data!$D$3:$D$16128='Надежда'!$B$1,ROW(data!$A$3:$A$16128)-ROW($A$3)+1),ROWS(B$4:B5))),"")} -> ЗАЕМ | C5: {=IF(ROWS(C$4:C5)<=$B$2,INDEX(data!B$3:B$16128,SMALL(IF(data!$D$3:$D$16128='Надежда'!$B$1,ROW(data!$A$3:$A$16128)-ROW($A$3)+1),ROWS(C$4:C5))),"")} -> 13260.68 | D5: {=IF(ROWS(D$4:D5)<=$B$2,INDEX(data!E$3:E$16128,SMALL(IF(data!$D$3:$D$16128='Надежда'!$B$1,ROW(data!$A$3:$A$16128)-ROW($A$3)+1),ROWS(D$4:D5))),"")} -> Салдо скл + вътр. п-не
A6: {=IF(ROWS(A$4:A6)<=$B$2,INDEX(data!C$3:C$16128,SMALL(IF(data!$D$3:$D$16128='Надежда'!$B$1,ROW(data!$A$3:$A$16128)-ROW($A$3)+1),ROWS(A$4:A6))),"")} -> 46027 | B6: {=IF(ROWS(B$4:B6)<=$B$2,INDEX(data!A$3:A$16128,SMALL(IF(data!$D$3:$D$16128='Надежда'!$B$1,ROW(data!$A$3:$A$16128)-ROW($A$3)+1),ROWS(B$4:B6))),"")} -> КАСОВА КНИГА | C6: {=IF(ROWS(C$4:C6)<=$B$2,INDEX(data!B$3:B$16128,SMALL(IF(data!$D$3:$D$16128='Надежда'!$B$1,ROW(data!$A$3:$A$16128)-ROW($A$3)+1),ROWS(C$4:C6))),"")} -> -1533.88 | D6: {=IF(ROWS(D$4:D6)<=$B$2,INDEX(data!E$3:E$16128,SMALL(IF(data!$D$3:$D$16128='Надежда'!$B$1,ROW(data!$A$3:$A$16128)-ROW($A$3)+1),ROWS(D$4:D6))),"")} -> банка 02.01
A7: {=IF(ROWS(A$4:A7)<=$B$2,INDEX(data!C$3:C$16128,SMALL(IF(data!$D$3:$D$16128='Надежда'!$B$1,ROW(data!$A$3:$A$16128)-ROW($A$3)+1),ROWS(A$4:A7))),"")} -> 46027 | B7: {=IF(ROWS(B$4:B7)<=$B$2,INDEX(data!A$3:A$16128,SMALL(IF(data!$D$3:$D$16128='Надежда'!$B$1,ROW(data!$A$3:$A$16128)-ROW($A$3)+1),ROWS(B$4:B7))),"")} -> КАСОВА КНИГА | C7: {=IF(ROWS(C$4:C7)<=$B$2,INDEX(data!B$3:B$16128,SMALL(IF(data!$D$3:$D$16128='Надежда'!$B$1,ROW(data!$A$3:$A$16128)-ROW($A$3)+1),ROWS(C$4:C7))),"")} -> -2556.46 | D7: {=IF(ROWS(D$4:D7)<=$B$2,INDEX(data!E$3:E$16128,SMALL(IF(data!$D$3:$D$16128='Надежда'!$B$1,ROW(data!$A$3:$A$16128)-ROW($A$3)+1),ROWS(D$4:D7))),"")} -> банка 03.01
A8: {=IF(ROWS(A$4:A8)<=$B$2,INDEX(data!C$3:C$16128,SMALL(IF(data!$D$3:$D$16128='Надежда'!$B$1,ROW(data!$A$3:$A$16128)-ROW($A$3)+1),ROWS(A$4:A8))),"")} -> 46027 | B8: {=IF(ROWS(B$4:B8)<=$B$2,INDEX(data!A$3:A$16128,SMALL(IF(data!$D$3:$D$16128='Надежда'!$B$1,ROW(data!$A$3:$A$16128)-ROW($A$3)+1),ROWS(B$4:B8))),"")} -> MYPOS Бакалия | C8: {=IF(ROWS(C$4:C8)<=$B$2,INDEX(data!B$3:B$16128,SMALL(IF(data!$D$3:$D$16128='Надежда'!$B$1,ROW(data!$A$3:$A$16128)-ROW($A$3)+1),ROWS(C$4:C8))),"")} -> -1530.29 | D8: {=IF(ROWS(D$4:D8)<=$B$2,INDEX(data!E$3:E$16128,SMALL(IF(data!$D$3:$D$16128='Надежда'!$B$1,ROW(data!$A$3:$A$16128)-ROW($A$3)+1),ROWS(D$4:D8))),"")}
A9: {=IF(ROWS(A$4:A9)<=$B$2,INDEX(data!C$3:C$16128,SMALL(IF(data!$D$3:$D$16128='Надежда'!$B$1,ROW(data!$A$3:$A$16128)-ROW($A$3)+1),ROWS(A$4:A9))),"")} -> 46027 | B9: {=IF(ROWS(B$4:B9)<=$B$2,INDEX(data!A$3:A$16128,SMALL(IF(data!$D$3:$D$16128='Надежда'!$B$1,ROW(data!$A$3:$A$16128)-ROW($A$3)+1),ROWS(B$4:B9))),"")} -> каса ФИКТИВНА | C9: {=IF(ROWS(C$4:C9)<=$B$2,INDEX(data!B$3:B$16128,SMALL(IF(data!$D$3:$D$16128='Надежда'!$B$1,ROW(data!$A$3:$A$16128)-ROW($A$3)+1),ROWS(C$4:C9))),"")} -> -176.4 | D9: {=IF(ROWS(D$4:D9)<=$B$2,INDEX(data!E$3:E$16128,SMALL(IF(data!$D$3:$D$16128='Надежда'!$B$1,ROW(data!$A$3:$A$16128)-ROW($A$3)+1),ROWS(D$4:D9))),"")} -> 2 колета Милена
A10: {=IF(ROWS(A$4:A10)<=$B$2,INDEX(data!C$3:C$16128,SMALL(IF(data!$D$3:$D$16128='Надежда'!$B$1,ROW(data!$A$3:$A$16128)-ROW($A$3)+1),ROWS(A$4:A10))),"")} -> 46027 | B10: {=IF(ROWS(B$4:B10)<=$B$2,INDEX(data!A$3:A$16128,SMALL(IF(data!$D$3:$D$16128='Надежда'!$B$1,ROW(data!$A$3:$A$16128)-ROW($A$3)+1),ROWS(B$4:B10))),"")} -> MYPOS Бакалия | C10: {=IF(ROWS(C$4:C10)<=$B$2,INDEX(data!B$3:B$16128,SMALL(IF(data!$D$3:$D$16128='Надежда'!$B$1,ROW(data!$A$3:$A$16128)-ROW($A$3)+1),ROWS(C$4:C10))),"")} -> -2004.8 | D10: {=IF(ROWS(D$4:D10)<=$B$2,INDEX(data!E$3:E$16128,SMALL(IF(data!$D$3:$D$16128='Надежда'!$B$1,ROW(data!$A$3:$A$16128)-ROW($A$3)+1),ROWS(D$4:D10))),"")} -> 29-31,12
A11: {=IF(ROWS(A$4:A11)<=$B$2,INDEX(data!C$3:C$16128,SMALL(IF(data!$D$3:$D$16128='Надежда'!$B$1,ROW(data!$A$3:$A$16128)-ROW($A$3)+1),ROWS(A$4:A11))),"")} -> 46027 | B11: {=IF(ROWS(B$4:B11)<=$B$2,INDEX(data!A$3:A$16128,SMALL(IF(data!$D$3:$D$16128='Надежда'!$B$1,ROW(data!$A$3:$A$16128)-ROW($A$3)+1),ROWS(B$4:B11))),"")} -> КАСОВА КНИГА | C11: {=IF(ROWS(C$4:C11)<=$B$2,INDEX(data!B$3:B$16128,SMALL(IF(data!$D$3:$D$16128='Надежда'!$B$1,ROW(data!$A$3:$A$16128)-ROW($A$3)+1),ROWS(C$4:C11))),"")} -> 7665 | D11: {=IF(ROWS(D$4:D11)<=$B$2,INDEX(data!E$3:E$16128,SMALL(IF(data!$D$3:$D$16128='Надежда'!$B$1,ROW(data!$A$3:$A$16128)-ROW($A$3)+1),ROWS(D$4:D11))),"")} -> евро
A12: {=IF(ROWS(A$4:A12)<=$B$2,INDEX(data!C$3:C$16128,SMALL(IF(data!$D$3:$D$16128='Надежда'!$B$1,ROW(data!$A$3:$A$16128)-ROW($A$3)+1),ROWS(A$4:A12))),"")} -> 46028 | B12: {=IF(ROWS(B$4:B12)<=$B$2,INDEX(data!A$3:A$16128,SMALL(IF(data!$D$3:$D$16128='Надежда'!$B$1,ROW(data!$A$3:$A$16128)-ROW($A$3)+1),ROWS(B$4:B12))),"")} -> ДСК Бакалия | C12: {=IF(ROWS(C$4:C12)<=$B$2,INDEX(data!B$3:B$16128,SMALL(IF(data!$D$3:$D$16128='Надежда'!$B$1,ROW(data!$A$3:$A$16128)-ROW($A$3)+1),ROWS(C$4:C12))),"")} -> -1533.88 | D12: {=IF(ROWS(D$4:D12)<=$B$2,INDEX(data!E$3:E$16128,SMALL(IF(data!$D$3:$D$16128='Надежда'!$B$1,ROW(data!$A$3:$A$16128)-ROW($A$3)+1),ROWS(D$4:D12))),"")}
A13: {=IF(ROWS(A$4:A13)<=$B$2,INDEX(data!C$3:C$16128,SMALL(IF(data!$D$3:$D$16128='Надежда'!$B$1,ROW(data!$A$3:$A$16128)-ROW($A$3)+1),ROWS(A$4:A13))),"")} -> 46029 | B13: {=IF(ROWS(B$4:B13)<=$B$2,INDEX(data!A$3:A$16128,SMALL(IF(data!$D$3:$D$16128='Надежда'!$B$1,ROW(data!$A$3:$A$16128)-ROW($A$3)+1),ROWS(B$4:B13))),"")} -> КАСОВА КНИГА | C13: {=IF(ROWS(C$4:C13)<=$B$2,INDEX(data!B$3:B$16128,SMALL(IF(data!$D$3:$D$16128='Надежда'!$B$1,ROW(data!$A$3:$A$16128)-ROW($A$3)+1),ROWS(C$4:C13))),"")} -> -1533.88 | D13: {=IF(ROWS(D$4:D13)<=$B$2,INDEX(data!E$3:E$16128,SMALL(IF(data!$D$3:$D$16128='Надежда'!$B$1,ROW(data!$A$3:$A$16128)-ROW($A$3)+1),ROWS(D$4:D13))),"")}
